Workbook
Name C0: aux!$B$23
Name Co: aux!$B$23
Name Co_BPCS: #REF!
Name Co_STAT: #REF!
Name fg: [1]Data_AC!$B$2
Name G: [1]Data_DC!$B$2
Name Gref: [1]Data_DC!$D$2
Name I_set: Capability!$D$33
Name Ii: Capability!$B$21
Name Ii_r: aux!$B$1
Name ImaxVdc: aux!$B$2
Name Iset: Capability!$D$33
Name K_1: aux!$B$26
Name K_2: aux!$B$27
Name K_3: aux!$B$28
Name K_4: aux!$B$29
Name Li: aux!$B$22
Name Li_BPCS: [1]Data_AC!$N$3
Name Li_STAT: [1]Data_AC!$R$3
Name Lo: aux!$B$24
Name Lo_BPCS: [1]Data_AC!$N$4
Name Lo_STAT: [1]Data_AC!$R$4
Name Nm: Capability!$B$4
Name Vac_to_Vdc: 1.43
Name Vdc_offset: 10
Name Vi: Capability!$B$20
Name Vo: Capability!$B$3
Name Vo_1: Capability!$B$3
Name wg: Capability!$D$5

Sheet Datasheet
A1: DC Input | B1: =CONCATENATE("1MWD3-V",Capability!$B$1) -> 1MWD3-V620 | D1: =CONCATENATE("2MWD3-V",Capability!$B$1) -> 2MWD3-V620 | F1: =CONCATENATE("3MWD3-V",Capability!$B$1) -> 3MWD3-V620 | M1: DC Input | N1: =CONCATENATE("1MWD3-V",Capability!$B$1) -> 1MWD3-V620 | Q1: DC Input | R1: =CONCATENATE("2MWD3-V",Capability!$B$1) -> 2MWD3-V620 | U1: DC Input | V1: =CONCATENATE("3MWD3-V",Capability!$B$1) -> 3MWD3-V620
B2: =CONCATENATE(B28,"WD3-HV",Capability!$B$1) -> 1258WD3-HV620 | D2: =CONCATENATE(D28,"WD3-HV",Capability!$B$1) -> 2517WD3-HV620 | F2: =CONCATENATE(F28,"WD3-HV",Capability!$B$1) -> 3775WD3-HV620 | N2: =CONCATENATE(N28,"WD3-HV",Capability!$B$1) -> 1258WD3-HV620 | R2: =CONCATENATE(R28,"WD3-HV",Capability!$B$1) -> 2517WD3-HV620 | V2: =F2 -> 3775WD3-HV620
B3: min | C3: max | D3: min | E3: max | F3: min | G3: max | N3: min | O3: max | R3: min | S3: max | V3: min | W3: max
A4: MPP Voltage range for PV [Vdc] | B4: =ROUNDUP(Capability!$B$1*Vac_to_Vdc+Vdc_offset*IF(Vo>500,IF(Vo>600,0,0.4),1),0) -> 887 | C4: 1500 | D4: =ROUNDUP(Capability!$B$1*Vac_to_Vdc+Vdc_offset*IF(Vo>500,IF(Vo>600,0,0.4),1),0) -> 887 | E4: 1500 | F4: =ROUNDUP(Capability!$B$1*Vac_to_Vdc+Vdc_offset*IF(Vo>500,IF(Vo>600,0,0.4),1),0) -> 887 | G4: 1500 | M4: MPP Voltage range for PV [Vdc] | N4: =ROUNDUP(Capability!$B$1*Vac_to_Vdc+Vdc_offset*IF(Vo>500,IF(Vo>600,0,0.4),1),0) -> 887 | O4: 1500 | Q4: MPP Voltage range for PV [Vdc] | R4: =ROUNDUP(Capability!$B$1*Vac_to_Vdc+Vdc_offset*IF(Vo>500,IF(Vo>600,0,0.4),1),0) -> 887 | S4: 1500 | U4: MPP Voltage range for PV [Vdc] | V4: =ROUNDUP(Capability!$B$1*Vac_to_Vdc+Vdc_offset*IF(Vo>500,IF(Vo>600,0,0.4),1),0) -> 887 | W4: 1500
A5: SOC Voltage range for BPCS [Vdc] | M5: SOC Voltage range for BPCS [Vdc] | Q5: SOC Voltage range for BPCS [Vdc] | U5: SOC Voltage range for BPCS [Vdc]
A6: MPP Voltage range @ full power [Vdc] (1) | B6: =ROUNDUP(Capability!$B$1*Vac_to_Vdc+Vdc_offset*IF(Vo>500,IF(Vo>600,0,0.4),1),0) -> 887 | C6: 1250 | D6: =ROUNDUP(Capability!$B$1*Vac_to_Vdc+Vdc_offset*IF(Vo>500,IF(Vo>600,0,0.4),1),0) -> 887 | E6: 1250 | F6: =ROUNDUP(Capability!$B$1*Vac_to_Vdc+Vdc_offset*IF(Vo>500,IF(Vo>600,0,0.4),1),0) -> 887 | G6: 1250 | M6: MPP Voltage range @ full power [Vdc] (1) | N6: =ROUNDUP(Capability!$B$1*Vac_to_Vdc+Vdc_offset*IF(Vo>500,IF(Vo>600,0,0.4),1),0) -> 887 | O6: 1250 | Q6: MPP Voltage range @ full power [Vdc] (1) | R6: =ROUNDUP(Capability!$B$1*Vac_to_Vdc+Vdc_offset*IF(Vo>500,IF(Vo>600,0,0.4),1),0) -> 887 | S6: 1250 | U6: MPP Voltage range @ full power [Vdc] (1) | V6: =ROUNDUP(Capability!$B$1*Vac_to_Vdc+Vdc_offset*IF(Vo>500,IF(Vo>600,0,0.4),1),0) -> 887 | W6: 1250
A7: SOC Voltage range @ full power [Vdc] (1) | M7: SOC Voltage range @ full power [Vdc] (1) | Q7: SOC Voltage range @ full power [Vdc] (1) | U7: SOC Voltage range @ full power [Vdc] (1)
A8: Max. DC voltage [Vdc] | B8: 1500 | D8: 1500 | F8: 1500 | M8: Max. DC voltage [Vdc] | N8: 1500 | Q8: Max. DC voltage [Vdc] | R8: 1500 | U8: Max. DC voltage [Vdc] | V8: 1500
A9: Rated input current at Vdc_min [A] @35ºC | B9: 1600 | D9: =B9*2 -> 3200 | F9: =B9*3 -> 4800 | M9: Rated input current at Vdc_min [A] @35ºC | N9: 1600 | Q9: Rated input current at Vdc_min [A] @35ºC | R9: =D9 -> 3200 | U9: Rated input current at Vdc_min [A] @35ºC | V9: =F9 -> 4800
A10: Rated input current at Vdc_min [A] @50ºC | B10: 1440 | D10: =B10*2 -> 2880 | F10: =B10*3 -> 4320 | M10: Rated input current at Vdc_min [A] @50ºC | N10: 1440 | Q10: Rated input current at Vdc_min [A] @50ºC | R10: =D10 -> 2880 | U10: Rated input current at Vdc_min [A] @50ºC | V10: =F10 -> 4320
A11: Max. Short circuit input current (2) | B11: 10000 | D11: 2x10000 | F11: 3x10000 | M11: Max. Short circuit input current (2) | N11: 10000 | Q11: Max. Short circuit input current (2) | R11: 2x10000 | U11: Max. Short circuit input current (2) | V11: 3x10000
A12: Number of MPPT | B12: 1 | D12: up to 2 | F12: up to 3 | M12: Number of MPPT | N12: 1 | Q12: Number of MPPT | R12: up to 2 | U12: Number of MPPT | V12: up to 3
A13: Switch type | B13: DC load break switch | M13: Switch type | N13: DC load break switch | Q13: Switch type | R13: =N13 -> DC load break switch | U13: Switch type | V13: =R13 -> DC load break switch
A14: DC overvoltage protection | B14: SPD (type 2) | M14: DC overvoltage protection | N14: SPD (type 2) | Q14: DC overvoltage protection | R14: =N14 -> SPD (type 2) | U14: DC overvoltage protection | V14: =R14 -> SPD (type 2)
A15: Number of DC Inputs | B15: up to 12 | D15: up to 24 | F15: Up to 36 | M15: Number of DC Inputs | N15: up to 12 | Q15: Number of DC Inputs | R15: up to 24 | U15: Number of DC Inputs | V15: Up to 36
A16: DC input protection (3) | B16: Fuses | M16: DC input protection (3) | N16: Fuses | Q16: DC input protection (3) | R16: =N16 -> Fuses | U16: DC input protection (3) | V16: =R16 -> Fuses
A17: Integrated DC monitoring | B17: Optional | M17: Integrated DC monitoring | N17: Optional | Q17: Integrated DC monitoring | R17: =N17 -> Optional | U17: Integrated DC monitoring | V17: =R17 -> Optional
A18: AC Output | M18: AC Output | Q18: AC Output | U18: AC Output
A19: Nominal AC voltage | B19: =Capability!$B$1 -> 620 | M19: Nominal AC voltage | N19: =Capability!$B$1 -> 620 | Q19: Nominal AC voltage | R19: =N19 -> 620 | U19: Nominal AC voltage | V19: =R19 -> 620
A20: Max. AC voltage range (4) | B20: 90%-110% | M20: Max. AC voltage range (4) | N20: 90%-110% | Q20: Max. AC voltage range (4) | R20: =N20 -> 90%-110% | U20: Max. AC voltage range (4) | V20: =R20 -> 90%-110%
A21: Frequency, f [Hz] | B21: 50-60 | M21: Frequency, f [Hz] | N21: 50-60 | Q21: Frequency, f [Hz] | R21: =N21 -> 50-60 | U21: Frequency, f [Hz] | V21: =R21 -> 50-60
A22: Frequency operation range [Hz] | B22: f ±3Hz | M22: Frequency operation range [Hz] | N22: f ±3Hz | Q22: Frequency operation range [Hz] | R22: =N22 -> f ±3Hz | U22: Frequency operation range [Hz] | V22: =R22 -> f ±3Hz
A23: =CONCATENATE("Rated apparent AC power [kVA] @", 9/5*H23+32,"ºF/",H23,"ºC up to ",I23,"Vdc (5)") -> Rated apparent AC power [kVA] @95ºF/35ºC up to 950Vdc (5) | B23: =ROUNDDOWN(Ii_r*J23*K23*Capability!$B$1*SQRT(3)/K_3^2/1000,0) -> 1455 | D23: =ROUNDDOWN(2*Ii_r*J23*K23*Capability!$B$1*SQRT(3)/K_3^2/1000,0) -> 2911 | F23: =ROUNDDOWN(3*Ii_r*J23*K23*Capability!$B$1*SQRT(3)/K_3^2/1000,0) -> 4367 | H23: 35 | I23: 950 | J23: =IF(H23>aux!$B$12,(H23-aux!$B$12)/(aux!$B$13-aux!$B$12)*(aux!$C$13-aux!$C$12)+aux!$C$12,IF(H23>aux!$B$11,(H23-aux!$B$11)/(aux!$B$12-aux!$B$11)*(aux!$C$12-aux!$C$11)+aux!$C$11,aux!$C$10)) -> 1.1161905 | K23: =IF(I23>aux!$B$20,0,IF(I23>aux!$B$19,(I23-aux!$B$19)*(aux!$C$19-aux!$C$20)/(aux!$B$19-aux!$B$20)+aux!$C$19,IF(I23>aux!$B$18,(aux!$C$18-aux!$C$19)/(aux!$B$18-aux!$B$19)*(I23-aux!$B$18)+aux!$C$18,IF(I23>aux!$B$17,(aux!$C$17-aux!$C$18)/(aux!$B$17-aux!$B$18)*(I23-aux!$B$17)+aux!$C$17,aux!$C$17)))) -> 1.15 | M23: =A23 -> Rated apparent AC power [kVA] @95ºF/35ºC up to 950Vdc (5) | N23: =B23 -> 1455 | Q23: =M23 -> Rated apparent AC power [kVA] @95ºF/35ºC up to 950Vdc (5) | R23: =D23 -> 2911 | U23: =Q23 -> Rated apparent AC power [kVA] @95ºF/35ºC up to 950Vdc (5) | V23: =F23 -> 4367
A24: =CONCATENATE("Rated apparent AC power [kVA] @", 9/5*H24+32,"ºF/",H24,"ºC up to ",I24,"Vdc (5)") -> Rated apparent AC power [kVA] @95ºF/35ºC up to 1250Vdc (5) | B24: =ROUNDDOWN(Ii_r*J24*K24*Capability!$B$1*SQRT(3)/K_3^2/1000,0) -> 1266 | D24: =ROUNDDOWN(2*Ii_r*J24*K24*Capability!$B$1*SQRT(3)/K_3^2/1000,0) -> 2532 | F24: =ROUNDDOWN(3*Ii_r*J24*K24*Capability!$B$1*SQRT(3)/K_3^2/1000,0) -> 3798 | H24: 35 | I24: 1250 | J24: =IF(H24>aux!$B$12,(H24-aux!$B$12)/(aux!$B$13-aux!$B$12)*(aux!$C$13-aux!$C$12)+aux!$C$12,IF(H24>aux!$B$11,(H24-aux!$B$11)/(aux!$B$12-aux!$B$11)*(aux!$C$12-aux!$C$11)+aux!$C$11,aux!$C$10)) -> 1.1161905 | K24: =IF(I24>aux!$B$20,0,IF(I24>aux!$B$19,(I24-aux!$B$19)*(aux!$C$19-aux!$C$20)/(aux!$B$19-aux!$B$20)+aux!$C$19,IF(I24>aux!$B$18,(aux!$C$18-aux!$C$19)/(aux!$B$18-aux!$B$19)*(I24-aux!$B$18)+aux!$C$18,IF(I24>aux!$B$17,(aux!$C$17-aux!$C$18)/(aux!$B$17-aux!$B$18)*(I24-aux!$B$17)+aux!$C$17,aux!$C$17)))) -> 1 | M24: =A24 -> Rated apparent AC power [kVA] @95ºF/35ºC up to 1250Vdc (5) | N24: =B24 -> 1266 | Q24: =M24 -> Rated apparent AC power [kVA] @95ºF/35ºC up to 1250Vdc (5) | R24: =D24 -> 2532 | U24: =Q24 -> Rated apparent AC power [kVA] @95ºF/35ºC up to 1250Vdc (5) | V24: =F24 -> 3798
A25: =CONCATENATE("Rated apparent AC power [kVA] @", 9/5*H25+32,"ºF/",H25,"ºC up to ",I25,"Vdc (5)") -> Rated apparent AC power [kVA] @122ºF/50ºC up to 950Vdc (5) | B25: =ROUNDDOWN(Ii_r*J25*K25*Capability!$B$1*SQRT(3)/K_3^2/1000,0) -> 1304 | D25: =ROUNDDOWN(2*Ii_r*J25*K25*Capability!$B$1*SQRT(3)/K_3^2/1000,0) -> 2608 | F25: =ROUNDDOWN(3*Ii_r*J25*K25*Capability!$B$1*SQRT(3)/K_3^2/1000,0) -> 3913 | H25: 50 | I25: 950 | J25: =IF(H25>aux!$B$12,(H25-aux!$B$12)/(aux!$B$13-aux!$B$12)*(aux!$C$13-aux!$C$12)+aux!$C$12,IF(H25>aux!$B$11,(H25-aux!$B$11)/(aux!$B$12-aux!$B$11)*(aux!$C$12-aux!$C$11)+aux!$C$11,aux!$C$10)) -> 1 | K25: =IF(I25>aux!$B$20,0,IF(I25>aux!$B$19,(I25-aux!$B$19)*(aux!$C$19-aux!$C$20)/(aux!$B$19-aux!$B$20)+aux!$C$19,IF(I25>aux!$B$18,(aux!$C$18-aux!$C$19)/(aux!$B$18-aux!$B$19)*(I25-aux!$B$18)+aux!$C$18,IF(I25>aux!$B$17,(aux!$C$17-aux!$C$18)/(aux!$B$17-aux!$B$18)*(I25-aux!$B$17)+aux!$C$17,aux!$C$17)))) -> 1.15 | M25: =A25 -> Rated apparent AC power [kVA] @122ºF/50ºC up to 950Vdc (5) | N25: =B25 -> 1304 | Q25: =M25 -> Rated apparent AC power [kVA] @122ºF/50ºC up to 950Vdc (5) | R25: =D25 -> 2608 | U25: =Q25 -> Rated apparent AC power [kVA] @122ºF/50ºC up to 950Vdc (5) | V25: =F25 -> 3913
A26: =CONCATENATE("Rated apparent AC power [kVA] @", 9/5*H26+32,"ºF/",H26,"ºC up to ",I26,"Vdc (5)") -> Rated apparent AC power [kVA] @122ºF/50ºC up to 1250Vdc (5) | B26: =ROUNDDOWN(Ii_r*J26*K26*Capability!$B$1*SQRT(3)/K_3^2/1000,0) -> 1134 | D26: =ROUNDDOWN(2*Ii_r*J26*K26*Capability!$B$1*SQRT(3)/K_3^2/1000,0) -> 2268 | F26: =ROUNDDOWN(3*Ii_r*J26*K26*Capability!$B$1*SQRT(3)/K_3^2/1000,0) -> 3402 | H26: 50 | I26: 1250 | J26: =IF(H26>aux!$B$12,(H26-aux!$B$12)/(aux!$B$13-aux!$B$12)*(aux!$C$13-aux!$C$12)+aux!$C$12,IF(H26>aux!$B$11,(H26-aux!$B$11)/(aux!$B$12-aux!$B$11)*(aux!$C$12-aux!$C$11)+aux!$C$11,aux!$C$10)) -> 1 | K26: =IF(I26>aux!$B$20,0,IF(I26>aux!$B$19,(I26-aux!$B$19)*(aux!$C$19-aux!$C$20)/(aux!$B$19-aux!$B$20)+aux!$C$19,IF(I26>aux!$B$18,(aux!$C$18-aux!$C$19)/(aux!$B$18-aux!$B$19)*(I26-aux!$B$18)+aux!$C$18,IF(I26>aux!$B$17,(aux!$C$17-aux!$C$18)/(aux!$B$17-aux!$B$18)*(I26-aux!$B$17)+aux!$C$17,aux!$C$17)))) -> 1 | M26: =A26 -> Rated apparent AC power [kVA] @122ºF/50ºC up to 1250Vdc (5) | N26: =B26 -> 1134 | Q26: =M26 -> Rated apparent AC power [kVA] @122ºF/50ºC up to 1250Vdc (5) | R26: =D26 -> 2268 | U26: =Q26 -> Rated apparent AC power [kVA] @122ºF/50ºC up to 1250Vdc (5) | V26: =F26 -> 3402
A27: =CONCATENATE("Rated AC power. Pmax [kW] @ ", 9/5*H26+32,"ºF/",H26,"ºC up to ",I26,"Vdc (5)") -> Rated AC power. Pmax [kW] @ 122ºF/50ºC up to 1250Vdc (5) | B27: =ROUNDDOWN(Ii_r*J27*K27*Capability!$B$1*SQRT(3)/1000,0) -> 1447 | D27: =ROUNDDOWN(2*Ii_r*J27*K27*Capability!$B$1*SQRT(3)/1000,0) -> 2894 | F27: =ROUNDDOWN(3*Ii_r*J27*K27*Capability!$B$1*SQRT(3)/1000,0) -> 4342 | H27: 35 | I27: 950 | J27: =IF(H27>aux!$B$12,(H27-aux!$B$12)/(aux!$B$13-aux!$B$12)*(aux!$C$13-aux!$C$12)+aux!$C$12,IF(H27>aux!$B$11,(H27-aux!$B$11)/(aux!$B$12-aux!$B$11)*(aux!$C$12-aux!$C$11)+aux!$C$11,aux!$C$10)) -> 1.1161905 | K27: =IF(I27>aux!$B$20,0,IF(I27>aux!$B$19,(I27-aux!$B$19)*(aux!$C$19-aux!$C$20)/(aux!$B$19-aux!$B$20)+aux!$C$19,IF(I27>aux!$B$18,(aux!$C$18-aux!$C$19)/(aux!$B$18-aux!$B$19)*(I27-aux!$B$18)+aux!$C$18,IF(I27>aux!$B$17,(aux!$C$17-aux!$C$18)/(aux!$B$17-aux!$B$18)*(I27-aux!$B$17)+aux!$C$17,aux!$C$17)))) -> 1.15 | M27: =A27 -> Rated AC power. Pmax [kW] @ 122ºF/50ºC up to 1250Vdc (5) | N27: =B27 -> 1447 | Q27: =M27 -> Rated AC power. Pmax [kW] @ 122ºF/50ºC up to 1250Vdc (5) | R27: =D27 -> 2894 | U27: =Q27 -> Rated AC power. Pmax [kW] @ 122ºF/50ºC up to 1250Vdc (5) | V27: =F27 -> 4342
A28: =CONCATENATE("Rated AC power. Pmax [kW] @ ", 9/5*H26+32,"ºF/",H26,"ºC up to ",I26,"Vdc (5)") -> Rated AC power. Pmax [kW] @ 122ºF/50ºC up to 1250Vdc (5) | B28: =ROUNDDOWN(Ii_r*J28*K28*Capability!$B$1*SQRT(3)/1000,0) -> 1258 | D28: =ROUNDDOWN(2*Ii_r*J28*K28*Capability!$B$1*SQRT(3)/1000,0) -> 2517 | F28: =ROUNDDOWN(3*Ii_r*J28*K28*Capability!$B$1*SQRT(3)/1000,0) -> 3775 | H28: 35 | I28: 1250 | J28: =IF(H28>aux!$B$12,(H28-aux!$B$12)/(aux!$B$13-aux!$B$12)*(aux!$C$13-aux!$C$12)+aux!$C$12,IF(H28>aux!$B$11,(H28-aux!$B$11)/(aux!$B$12-aux!$B$11)*(aux!$C$12-aux!$C$11)+aux!$C$11,aux!$C$10)) -> 1.1161905 | K28: =IF(I28>aux!$B$20,0,IF(I28>aux!$B$19,(I28-aux!$B$19)*(aux!$C$19-aux!$C$20)/(aux!$B$19-aux!$B$20)+aux!$C$19,IF(I28>aux!$B$18,(aux!$C$18-aux!$C$19)/(aux!$B$18-aux!$B$19)*(I28-aux!$B$18)+aux!$C$18,IF(I28>aux!$B$17,(aux!$C$17-aux!$C$18)/(aux!$B$17-aux!$B$18)*(I28-aux!$B$17)+aux!$C$17,aux!$C$17)))) -> 1 | M28: =A28 -> Rated AC power. Pmax [kW] @ 122ºF/50ºC up to 1250Vdc (5) | N28: =B28 -> 1258 | Q28: =M28 -> Rated AC power. Pmax [kW] @ 122ºF/50ºC up to 1250Vdc (5) | R28: =D28 -> 2517 | U28: =Q28 -> Rated AC power. Pmax [kW] @ 122ºF/50ºC up to 1250Vdc (5) | V28: =F28 -> 3775
A29: Total Current Demand Distortion (TDD) | B29: <3% | M29: Total Current Demand Distortion (TDD) | N29: <3% | Q29: Total Current Demand Distortion (TDD) | R29: =N29 -> <3% | U29: Total Current Demand Distortion (TDD) | V29: =R29 -> <3%
A30: Power factor | B30: Adjustable | M30: Power factor | N30: Adjustable | Q30: Power factor | R30: =N30 -> Adjustable | U30: Power factor | V30: =R30 -> Adjustable
A31: AC Cabinet | B31: Integrated | M31: AC Cabinet | N31: Integrated | Q31: AC Cabinet | R31: =N31 -> Integrated | U31: AC Cabinet | V31: =R31 -> Integrated
A32: Switch type | B32: AC circuit breaker | M32: Switch type | N32: AC circuit breaker | Q32: Switch type | R32: =N32 -> AC circuit breaker | U32: Switch type | V32: =R32 -> AC circuit breaker
A33: Number of handling switches | B33: 1 | D33: 2 | F33: 3 | M33: Number of handling switches | N33: 1 | Q33: Number of handling switches | R33: 2 | U33: Number of handling switches | V33: 3
A34: AC overvoltage protection | B34: SPD (type 2) | M34: AC overvoltage protection | N34: SPD (type 2) | Q34: AC overvoltage protection | R34: =N34 -> SPD (type 2) | U34: AC overvoltage protection | V34: =R34 -> SPD (type 2)
A35: Efficiency | M35: Efficiency | Q35: Efficiency | U35: Efficiency
A36: Maximum Peak Efficiency (7) | B36: =IF(Capability!$B$1>600,">98.8%",IF(Capability!$B$1>=560,">98.7%",IF(Capability!$B$1>500,">98.6%",">98.4%"))) -> >98.8% | M36: Maximum Peak Efficiency (7) | N36: =IF(Capability!$B$1>600,">98.8%",IF(Capability!$B$1>=560,">98.7%",IF(Capability!$B$1>500,">98.6%",">98.4%"))) -> >98.8% | Q36: Maximum Peak Efficiency (7) | R36: =N36 -> >98.8% | U36: Maximum Peak Efficiency (7) | V36: =R36 -> >98.8%
A37: European Efficiency (7) | B37: =IF(Capability!$B$1>600,">98.5%",IF(Capability!$B$1>=560,">98.5%",IF(Capability!$B$1>500,">98.4%",">98.1%"))) -> >98.5% | M37: European Efficiency (7) | N37: =IF(Capability!$B$1>600,">98.5%",IF(Capability!$B$1>=560,">98.5%",IF(Capability!$B$1>500,">98.4%",">98.1%"))) -> >98.5% | Q37: European Efficiency (7) | R37: =N37 -> >98.5% | U37: European Efficiency (7) | V37: =R37 -> >98.5%
A38: CEC Efficiency (7) | B38: =IF(Capability!$B$1>600,">98.6%",IF(Capability!$B$1>=560,">98.6%",IF(Capability!$B$1>500,">98.5%",">98.2%"))) -> >98.6% | M38: CEC Efficiency (7) | N38: =IF(Capability!$B$1>600,">98.6%",IF(Capability!$B$1>=560,">98.6%",IF(Capability!$B$1>500,">98.5%",">98.2%"))) -> >98.6% | Q38: CEC Efficiency (7) | R38: =N38 -> >98.6% | U38: CEC Efficiency (7) | V38: =R38 -> >98.6%
A39: Self-consumption in standby [W] (8) | B39: <250 | D39: <400 | F39: <550 | M39: Self-consumption in standby [W] (8) | N39: <250 | Q39: Self-consumption in standby [W] (8) | R39: <400 | U39: Self-consumption in standby [W] (8) | V39: <550
A40: Self-consumption in operation [kW] | B40: <4.5 | D40: <7 | F40: <10 | M40: Self-consumption in operation [kW] | N40: <4.5 | Q40: Self-consumption in operation [kW] | R40: <7 | U40: Self-consumption in operation [kW] | V40: <10
...

Sheet Capability
A1: Inverter Voltage | B1: 620 | H1: P (W) | I1: Q _Ii(VAr) | J1: Vi_need | K1: Q_Vdc (Var) | L1: Q(Var) | M1: P(kW) | N1: Q(kVAr) | O1: Q_Ii(kVAr) | P1: Vdc_min (V) | Q1: S(kVA) | R1: cos fi
A2: Voltage operation pu | B2: 1 | F2: P_manual (kW), Q>0 | G2: 3750 | H2: =G2*1000 -> 3750000 | I2: =Nm*(SQRT(IF(3/K_3^2*Ii^2*Vo^2-(H2/Nm)^2<0.0000000001,0,3/K_3^2*Ii^2*Vo^2-(H2/Nm)^2))+Vo^2/K_3*K_4) -> 1868166.1 | J2: =SQRT(3)*SQRT((Vo/SQRT(3)*K_1+SQRT(H2^2+I2^2)/SQRT(3)/Vo/Nm*I2/SQRT(H2^2+I2^2)*K_2)^2+(SQRT(H2^2+I2^2)/SQRT(3)/Vo/Nm*H2/SQRT(H2^2+I2^2)*K_2)^2) -> 666.47532 | K2: =Nm*(SQRT(Vi^2*Vo^2/K_2^2-(H2/Nm)^2)-Vo^2*K_1/K_2) -> 1825941.5 | L2: =IF(ABS(I2)<ABS(K2),I2,K2) -> 1825941.5 | M2: =H2/1000 -> 3750 | N2: =L2/1000 -> 1825.9415 | O2: =I2/1000 -> 1868.1661 | P2: =J2*1.43+10 -> 963.05971 | Q2: =SQRT(M2^2+N2^2) -> 4170.9186 | R2: =M2/SQRT(M2^2+N2^2) -> 0.89908251 | S2: Capacitive
A3: Line-Line Voltage (V) | B3: =$B$1*B2 -> 620 | F3: P_manual (kW), Q<0 | G3: 2846 | H3: =G3*1000 -> 2846000 | I3: =Nm*(-SQRT(IF(3/K_3^2*Ii^2*Vo^2-(H3/Nm)^2<0.0000000001,0,3/K_3^2*Ii^2*Vo^2-(H3/Nm)^2))+Vo^2/K_3*K_4) -> -2394824.4 | J3: =SQRT(3)*SQRT((Vo/SQRT(3)*K_1+SQRT(H3^2+I3^2)/SQRT(3)/Vo/Nm*I3/SQRT(H3^2+I3^2)*K_2)^2+(SQRT(H3^2+I3^2)/SQRT(3)/Vo/Nm*H3/SQRT(H3^2+I3^2)*K_2)^2) -> 552.93135 | K3: =Nm*(-SQRT(Vi^2*Vo^2/K_2^2-(H3/Nm)^2)-Vo^2*K_1/K_2) -> -48695325 | L3: =IF(ABS(I3)<ABS(K3),I3,K3) -> -2394824.4 | M3: =H3/1000 -> 2846 | N3: =L3/1000 -> -2394.8244 | O3: =I3/1000 -> -2394.8244 | P3: =J3*1.43+10 -> 800.69183 | Q3: =SQRT(M3^2+N3^2) -> 3719.5295 | R3: =M3/SQRT(M3^2+N3^2) -> 0.76515054 | S3: Inductive
A4: Nm: Number of modules | B4: 3 | H4: =0 -> 0 | I4: =Nm*(SQRT(IF(3/K_3^2*Ii^2*Vo^2-(H4/Nm)^2<0.0000000001,0,3/K_3^2*Ii^2*Vo^2-(H4/Nm)^2))+Vo^2/K_3*K_4) -> 4450198.8 | J4: =SQRT(3)*SQRT((Vo/SQRT(3)*K_1+SQRT(H4^2+I4^2)/SQRT(3)/Vo/Nm*I4/SQRT(H4^2+I4^2)*K_2)^2+(SQRT(H4^2+I4^2)/SQRT(3)/Vo/Nm*H4/SQRT(H4^2+I4^2)*K_2)^2) -> 726.67073 | K4: =Nm*(SQRT(Vi^2*Vo^2/K_2^2-(H4/Nm)^2)-Vo^2*K_1/K_2) -> 2103413.9 | L4: =IF(ABS(I4)<ABS(K4),I4,K4) -> 2103413.9 | M4: =IF(H4/1000>$D$23,$D$23,H4/1000) -> 0 | N4: =L4/1000 -> 2103.4139 | O4: =I4/1000 -> 4450.1988 | P4: =J4*1.43+10 -> 1049.1391 | Q4: =SQRT(M4^2+N4^2) -> 2103.4139 | R4: =M4/SQRT(M4^2+N4^2) -> 0
A5: f(Hz) | B5: 50 | C5: wg(Hz) | D5: =2*PI()*B5 -> 314.15927 | H5: =$B$23/20+H4 -> 200113.81 | I5: =Nm*(SQRT(IF(3/K_3^2*Ii^2*Vo^2-(H5/Nm)^2<0.0000000001,0,3/K_3^2*Ii^2*Vo^2-(H5/Nm)^2))+Vo^2/K_3*K_4) -> 4445207.7 | J5: =SQRT(3)*SQRT((Vo/SQRT(3)*K_1+SQRT(H5^2+I5^2)/SQRT(3)/Vo/Nm*I5/SQRT(H5^2+I5^2)*K_2)^2+(SQRT(H5^2+I5^2)/SQRT(3)/Vo/Nm*H5/SQRT(H5^2+I5^2)*K_2)^2) -> 726.55918 | K5: =Nm*(SQRT(Vi^2*Vo^2/K_2^2-(H5/Nm)^2)-Vo^2*K_1/K_2) -> 2102628 | L5: =IF(ABS(I5)<ABS(K5),I5,K5) -> 2102628 | M5: =IF(H5/1000>$D$23,$D$23,H5/1000) -> 200.11381 | N5: =L5/1000 -> 2102.628 | O5: =I5/1000 -> 4445.2077 | P5: =J5*1.43+10 -> 1048.9796 | Q5: =SQRT(M5^2+N5^2) -> 2112.1293 | R5: =M5/SQRT(M5^2+N5^2) -> 0.094745056
A6: Height (m) | B6: 2700 | H6: =$B$22/20+H5 -> 401417.92 | I6: =Nm*(SQRT(IF(3/K_3^2*Ii^2*Vo^2-(H6/Nm)^2<0.0000000001,0,3/K_3^2*Ii^2*Vo^2-(H6/Nm)^2))+Vo^2/K_3*K_4) -> 4430077.4 | J6: =SQRT(3)*SQRT((Vo/SQRT(3)*K_1+SQRT(H6^2+I6^2)/SQRT(3)/Vo/Nm*I6/SQRT(H6^2+I6^2)*K_2)^2+(SQRT(H6^2+I6^2)/SQRT(3)/Vo/Nm*H6/SQRT(H6^2+I6^2)*K_2)^2) -> 726.22092 | K6: =Nm*(SQRT(Vi^2*Vo^2/K_2^2-(H6/Nm)^2)-Vo^2*K_1/K_2) -> 2100251.5 | L6: =IF(ABS(I6)<ABS(K6),I6,K6) -> 2100251.5 | M6: =IF(H6/1000>$D$23,$D$23,H6/1000) -> 401.41792 | N6: =L6/1000 -> 2100.2515 | O6: =I6/1000 -> 4430.0774 | P6: =J6*1.43+10 -> 1048.4959 | Q6: =SQRT(M6^2+N6^2) -> 2138.2687 | R6: =M6/SQRT(M6^2+N6^2) -> 0.18773035
A7: Temperature Max (ºC) ( TM) | B7: 33 | C7: TM_H_corrected(ºC) | D7: =B7+aux!C6 -> 44.25 | H7: =$B$22/20+H6 -> 602722.04 | I7: =Nm*(SQRT(IF(3/K_3^2*Ii^2*Vo^2-(H7/Nm)^2<0.0000000001,0,3/K_3^2*Ii^2*Vo^2-(H7/Nm)^2))+Vo^2/K_3*K_4) -> 4404691.8 | J7: =SQRT(3)*SQRT((Vo/SQRT(3)*K_1+SQRT(H7^2+I7^2)/SQRT(3)/Vo/Nm*I7/SQRT(H7^2+I7^2)*K_2)^2+(SQRT(H7^2+I7^2)/SQRT(3)/Vo/Nm*H7/SQRT(H7^2+I7^2)*K_2)^2) -> 725.65305 | K7: =Nm*(SQRT(Vi^2*Vo^2/K_2^2-(H7/Nm)^2)-Vo^2*K_1/K_2) -> 2096284 | L7: =IF(ABS(I7)<ABS(K7),I7,K7) -> 2096284 | M7: =IF(H7/1000>$D$23,$D$23,H7/1000) -> 602.72204 | N7: =L7/1000 -> 2096.284 | O7: =I7/1000 -> 4404.6918 | P7: =J7*1.43+10 -> 1047.6839 | Q7: =SQRT(M7^2+N7^2) -> 2181.2108 | R7: =M7/SQRT(M7^2+N7^2) -> 0.27632453
A8: Vdc_min (Tmax) | B8: 951.5 | C8: Vdc_min(sat) | D8: =IF(B8>1250,1250,IF(B8<$B$3*Vac_to_Vdc+Vdc_offset*Vdc_offset*IF(Vo>500,IF(Vo>600,0,0.4),1),$B$3*Vac_to_Vdc+Vdc_offset*IF(Vo>500,IF(Vo>600,0,0.4),1),B8)) -> 951.5 | H8: =$B$22/20+H7 -> 804026.16 | I8: =Nm*(SQRT(IF(3/K_3^2*Ii^2*Vo^2-(H8/Nm)^2<0.0000000001,0,3/K_3^2*Ii^2*Vo^2-(H8/Nm)^2))+Vo^2/K_3*K_4) -> 4368852.4 | J8: =SQRT(3)*SQRT((Vo/SQRT(3)*K_1+SQRT(H8^2+I8^2)/SQRT(3)/Vo/Nm*I8/SQRT(H8^2+I8^2)*K_2)^2+(SQRT(H8^2+I8^2)/SQRT(3)/Vo/Nm*H8/SQRT(H8^2+I8^2)*K_2)^2) -> 724.85055 | K8: =Nm*(SQRT(Vi^2*Vo^2/K_2^2-(H8/Nm)^2)-Vo^2*K_1/K_2) -> 2090724.7 | L8: =IF(ABS(I8)<ABS(K8),I8,K8) -> 2090724.7 | M8: =IF(H8/1000>$D$23,$D$23,H8/1000) -> 804.02616 | N8: =L8/1000 -> 2090.7247 | O8: =I8/1000 -> 4368.8524 | P8: =J8*1.43+10 -> 1046.5363 | Q8: =SQRT(M8^2+N8^2) -> 2239.9972 | R8: =M8/SQRT(M8^2+N8^2) -> 0.35894069
A9: TM_derating | B9: =IF(B25=1,IF(D7>aux!B12,(D7-aux!B12)/(aux!B13-aux!B12)*(aux!C13-aux!C12)+aux!C12,IF(D7>aux!B11,(D7-aux!B11)/(aux!B12-aux!B11)*(aux!C12-aux!C11)+aux!C11,aux!C10)),1) -> 1.0445397 | H9: =$B$22/20+H8 -> 1005330.3 | I9: =Nm*(SQRT(IF(3/K_3^2*Ii^2*Vo^2-(H9/Nm)^2<0.0000000001,0,3/K_3^2*Ii^2*Vo^2-(H9/Nm)^2))+Vo^2/K_3*K_4) -> 4322269.9 | J9: =SQRT(3)*SQRT((Vo/SQRT(3)*K_1+SQRT(H9^2+I9^2)/SQRT(3)/Vo/Nm*I9/SQRT(H9^2+I9^2)*K_2)^2+(SQRT(H9^2+I9^2)/SQRT(3)/Vo/Nm*H9/SQRT(H9^2+I9^2)*K_2)^2) -> 723.80618 | K9: =Nm*(SQRT(Vi^2*Vo^2/K_2^2-(H9/Nm)^2)-Vo^2*K_1/K_2) -> 2083572.5 | L9: =IF(ABS(I9)<ABS(K9),I9,K9) -> 2083572.5 | M9: =IF(H9/1000>$D$23,$D$23,H9/1000) -> 1005.3303 | N9: =L9/1000 -> 2083.5725 | O9: =I9/1000 -> 4322.2699 | P9: =J9*1.43+10 -> 1045.0428 | Q9: =SQRT(M9^2+N9^2) -> 2313.431 | R9: =M9/SQRT(M9^2+N9^2) -> 0.43456246
A10: Vdc_min derating | B10: =IF(B25=1,IF(D8>aux!B20,0,IF(D8>aux!B19,(D8-aux!B19)*(aux!C19-aux!C20)/(aux!B19-aux!B20)+aux!C19,IF(D8>aux!B18,(aux!C18-aux!C19)/(aux!B18-aux!B19)*(D8-aux!B18)+aux!C18,IF(D8>aux!B17,(aux!C17-aux!C18)/(aux!B17-aux!B18)*(D8-aux!B17)+aux!C17,aux!C17)))),1) -> 1.14925 | H10: =$B$22/20+H9 -> 1206634.4 | I10: =Nm*(SQRT(IF(3/K_3^2*Ii^2*Vo^2-(H10/Nm)^2<0.0000000001,0,3/K_3^2*Ii^2*Vo^2-(H10/Nm)^2))+Vo^2/K_3*K_4) -> 4264552.2 | J10: =SQRT(3)*SQRT((Vo/SQRT(3)*K_1+SQRT(H10^2+I10^2)/SQRT(3)/Vo/Nm*I10/SQRT(H10^2+I10^2)*K_2)^2+(SQRT(H10^2+I10^2)/SQRT(3)/Vo/Nm*H10/SQRT(H10^2+I10^2)*K_2)^2) -> 722.51006 | K10: =Nm*(SQRT(Vi^2*Vo^2/K_2^2-(H10/Nm)^2)-Vo^2*K_1/K_2) -> 2074826 | L10: =IF(ABS(I10)<ABS(K10),I10,K10) -> 2074826 | M10: =IF(H10/1000>$D$23,$D$23,H10/1000) -> 1206.6344 | N10: =L10/1000 -> 2074.826 | O10: =I10/1000 -> 4264.5522 | P10: =J10*1.43+10 -> 1043.1894 | Q10: =SQRT(M10^2+N10^2) -> 2400.1812 | R10: =M10/SQRT(M10^2+N10^2) -> 0.50272638
A11: Total derating@ TM | B11: =B9*B10 -> 1.2004372 | H11: =$B$22/20+H10 -> 1407938.5 | I11: =Nm*(SQRT(IF(3/K_3^2*Ii^2*Vo^2-(H11/Nm)^2<0.0000000001,0,3/K_3^2*Ii^2*Vo^2-(H11/Nm)^2))+Vo^2/K_3*K_4) -> 4195186.4 | J11: =SQRT(3)*SQRT((Vo/SQRT(3)*K_1+SQRT(H11^2+I11^2)/SQRT(3)/Vo/Nm*I11/SQRT(H11^2+I11^2)*K_2)^2+(SQRT(H11^2+I11^2)/SQRT(3)/Vo/Nm*H11/SQRT(H11^2+I11^2)*K_2)^2) -> 720.94929 | K11: =Nm*(SQRT(Vi^2*Vo^2/K_2^2-(H11/Nm)^2)-Vo^2*K_1/K_2) -> 2064483.8 | L11: =IF(ABS(I11)<ABS(K11),I11,K11) -> 2064483.8 | M11: =IF(H11/1000>$D$23,$D$23,H11/1000) -> 1407.9385 | N11: =L11/1000 -> 2064.4838 | O11: =I11/1000 -> 4195.1864 | P11: =J11*1.43+10 -> 1040.9575 | Q11: =SQRT(M11^2+N11^2) -> 2498.8766 | R11: =M11/SQRT(M11^2+N11^2) -> 0.56342859
A12: Temperature Min (ºC) ( Tm) | B12: -5 | C12: Tm_H_corrected(ºC) | D12: =B12+aux!C6 -> 6.25 | H12: =$B$22/20+H11 -> 1609242.6 | I12: =Nm*(SQRT(IF(3/K_3^2*Ii^2*Vo^2-(H12/Nm)^2<0.0000000001,0,3/K_3^2*Ii^2*Vo^2-(H12/Nm)^2))+Vo^2/K_3*K_4) -> 4113513.4 | J12: =SQRT(3)*SQRT((Vo/SQRT(3)*K_1+SQRT(H12^2+I12^2)/SQRT(3)/Vo/Nm*I12/SQRT(H12^2+I12^2)*K_2)^2+(SQRT(H12^2+I12^2)/SQRT(3)/Vo/Nm*H12/SQRT(H12^2+I12^2)*K_2)^2) -> 719.10726 | K12: =Nm*(SQRT(Vi^2*Vo^2/K_2^2-(H12/Nm)^2)-Vo^2*K_1/K_2) -> 2052543.7 | L12: =IF(ABS(I12)<ABS(K12),I12,K12) -> 2052543.7 | M12: =IF(H12/1000>$D$23,$D$23,H12/1000) -> 1609.2426 | N12: =L12/1000 -> 2052.5437 | O12: =I12/1000 -> 4113.5134 | P12: =J12*1.43+10 -> 1038.3234 | Q12: =SQRT(M12^2+N12^2) -> 2608.179 | R12: =M12/SQRT(M12^2+N12^2) -> 0.61699854
A13: Vdc_MPPT (Tmin) | B13: 1130 | C13: Vdc_max(sat) | D13: =IF(B13>1250,1250,IF(B13<Vo*1.43,Vo*1.43,B13)) -> 1130 | H13: =$B$22/20+H12 -> 1810546.7 | I13: =Nm*(SQRT(IF(3/K_3^2*Ii^2*Vo^2-(H13/Nm)^2<0.0000000001,0,3/K_3^2*Ii^2*Vo^2-(H13/Nm)^2))+Vo^2/K_3*K_4) -> 4018691.8 | J13: =SQRT(3)*SQRT((Vo/SQRT(3)*K_1+SQRT(H13^2+I13^2)/SQRT(3)/Vo/Nm*I13/SQRT(H13^2+I13^2)*K_2)^2+(SQRT(H13^2+I13^2)/SQRT(3)/Vo/Nm*H13/SQRT(H13^2+I13^2)*K_2)^2) -> 716.96274 | K13: =Nm*(SQRT(Vi^2*Vo^2/K_2^2-(H13/Nm)^2)-Vo^2*K_1/K_2) -> 2039003.6 | L13: =IF(ABS(I13)<ABS(K13),I13,K13) -> 2039003.6 | M13: =IF(H13/1000>$D$23,$D$23,H13/1000) -> 1810.5467 | N13: =L13/1000 -> 2039.0036 | O13: =I13/1000 -> 4018.6918 | P13: =J13*1.43+10 -> 1035.2567 | Q13: =SQRT(M13^2+N13^2) -> 2726.8325 | R13: =M13/SQRT(M13^2+N13^2) -> 0.66397432
A14: Tm_derating | B14: =IF(B25=1,IF(D12>aux!B12,(D12-aux!B12)/(aux!B13-aux!B12)*(aux!C13-aux!C12)+aux!C12,IF(D12>aux!B11,(D12-aux!B11)/(aux!B12-aux!B11)*(aux!C12-aux!C11)+aux!C11,aux!C10)),1) -> 1.1161905 | H14: =$B$22/20+H13 -> 2011850.9 | I14: =Nm*(SQRT(IF(3/K_3^2*Ii^2*Vo^2-(H14/Nm)^2<0.0000000001,0,3/K_3^2*Ii^2*Vo^2-(H14/Nm)^2))+Vo^2/K_3*K_4) -> 3909644.8 | J14: =SQRT(3)*SQRT((Vo/SQRT(3)*K_1+SQRT(H14^2+I14^2)/SQRT(3)/Vo/Nm*I14/SQRT(H14^2+I14^2)*K_2)^2+(SQRT(H14^2+I14^2)/SQRT(3)/Vo/Nm*H14/SQRT(H14^2+I14^2)*K_2)^2) -> 714.48854 | K14: =Nm*(SQRT(Vi^2*Vo^2/K_2^2-(H14/Nm)^2)-Vo^2*K_1/K_2) -> 2023860.9 | L14: =IF(ABS(I14)<ABS(K14),I14,K14) -> 2023860.9 | M14: =IF(H14/1000>$D$23,$D$23,H14/1000) -> 2011.8509 | N14: =L14/1000 -> 2023.8609 | O14: =I14/1000 -> 3909.6448 | P14: =J14*1.43+10 -> 1031.7186 | Q14: =SQRT(M14^2+N14^2) -> 2853.6918 | R14: =M14/SQRT(M14^2+N14^2) -> 0.70499934
A15: Vdc_derating(V) | B15: =IF(B25=1,IF(B13>aux!B20,0,IF(B13>aux!B19,(B13-aux!B19)*(aux!C19-aux!C20)/(aux!B19-aux!B20)+aux!C19,IF(B13>aux!B18,(aux!C18-aux!C19)/(aux!B18-aux!B19)*(B13-aux!B18)+aux!C18,IF(B13>aux!B17,(aux!C17-aux!C18)/(aux!B17-aux!B18)*(B13-aux!B17)+aux!C17,aux!C17)))),1) -> 1.06 | H15: =$B$22/20+H14 -> 2213155 | I15: =Nm*(SQRT(IF(3/K_3^2*Ii^2*Vo^2-(H15/Nm)^2<0.0000000001,0,3/K_3^2*Ii^2*Vo^2-(H15/Nm)^2))+Vo^2/K_3*K_4) -> 3784983.1 | J15: =SQRT(3)*SQRT((Vo/SQRT(3)*K_1+SQRT(H15^2+I15^2)/SQRT(3)/Vo/Nm*I15/SQRT(H15^2+I15^2)*K_2)^2+(SQRT(H15^2+I15^2)/SQRT(3)/Vo/Nm*H15/SQRT(H15^2+I15^2)*K_2)^2) -> 711.64951 | K15: =Nm*(SQRT(Vi^2*Vo^2/K_2^2-(H15/Nm)^2)-Vo^2*K_1/K_2) -> 2007112.8 | L15: =IF(ABS(I15)<ABS(K15),I15,K15) -> 2007112.8 | M15: =IF(H15/1000>$D$23,$D$23,H15/1000) -> 2213.155 | N15: =L15/1000 -> 2007.1128 | O15: =I15/1000 -> 3784.9831 | P15: =J15*1.43+10 -> 1027.6588 | Q15: =SQRT(M15^2+N15^2) -> 2987.7344 | R15: =M15/SQRT(M15^2+N15^2) -> 0.7407469
A16: Total derating@ Tm | B16: =B14*B15 -> 1.1831619 | H16: =$B$22/20+H15 -> 2414459.1 | I16: =Nm*(SQRT(IF(3/K_3^2*Ii^2*Vo^2-(H16/Nm)^2<0.0000000001,0,3/K_3^2*Ii^2*Vo^2-(H16/Nm)^2))+Vo^2/K_3*K_4) -> 3642886.2 | J16: =SQRT(3)*SQRT((Vo/SQRT(3)*K_1+SQRT(H16^2+I16^2)/SQRT(3)/Vo/Nm*I16/SQRT(H16^2+I16^2)*K_2)^2+(SQRT(H16^2+I16^2)/SQRT(3)/Vo/Nm*H16/SQRT(H16^2+I16^2)*K_2)^2) -> 708.39954 | K16: =Nm*(SQRT(Vi^2*Vo^2/K_2^2-(H16/Nm)^2)-Vo^2*K_1/K_2) -> 1988756 | L16: =IF(ABS(I16)<ABS(K16),I16,K16) -> 1988756 | M16: =IF(H16/1000>$D$23,$D$23,H16/1000) -> 2414.4591 | N16: =L16/1000 -> 1988.756 | O16: =I16/1000 -> 3642.8862 | P16: =J16*1.43+10 -> 1023.0113 | Q16: =SQRT(M16^2+N16^2) -> 3128.0606 | R16: =M16/SQRT(M16^2+N16^2) -> 0.77187095
H17: =$B$22/20+H16 -> 2615763.2 | I17: =Nm*(SQRT(IF(3/K_3^2*Ii^2*Vo^2-(H17/Nm)^2<0.0000000001,0,3/K_3^2*Ii^2*Vo^2-(H17/Nm)^2))+Vo^2/K_3*K_4) -> 3480914.2 | J17: =SQRT(3)*SQRT((Vo/SQRT(3)*K_1+SQRT(H17^2+I17^2)/SQRT(3)/Vo/Nm*I17/SQRT(H17^2+I17^2)*K_2)^2+(SQRT(H17^2+I17^2)/SQRT(3)/Vo/Nm*H17/SQRT(H17^2+I17^2)*K_2)^2) -> 704.67671 | K17: =Nm*(SQRT(Vi^2*Vo^2/K_2^2-(H17/Nm)^2)-Vo^2*K_1/K_2) -> 1968787 | L17: =IF(ABS(I17)<ABS(K17),I17,K17) -> 1968787 | M17: =IF(H17/1000>$D$23,$D$23,H17/1000) -> 2615.7632 | N17: =L17/1000 -> 1968.787 | O17: =I17/1000 -> 3480.9142 | P17: =J17*1.43+10 -> 1017.6877 | Q17: =SQRT(M17^2+N17^2) -> 3273.8875 | R17: =M17/SQRT(M17^2+N17^2) -> 0.79897773
A18: Derating factor for TM | B18: =MIN(B16,B11) -> 1.1831619 | H18: =$B$22/20+H17 -> 2817067.3 | I18: =Nm*(SQRT(IF(3/K_3^2*Ii^2*Vo^2-(H18/Nm)^2<0.0000000001,0,3/K_3^2*Ii^2*Vo^2-(H18/Nm)^2))+Vo^2/K_3*K_4) -> 3295691.9 | J18: =SQRT(3)*SQRT((Vo/SQRT(3)*K_1+SQRT(H18^2+I18^2)/SQRT(3)/Vo/Nm*I18/SQRT(H18^2+I18^2)*K_2)^2+(SQRT(H18^2+I18^2)/SQRT(3)/Vo/Nm*H18/SQRT(H18^2+I18^2)*K_2)^2) -> 700.39524 | K18: =Nm*(SQRT(Vi^2*Vo^2/K_2^2-(H18/Nm)^2)-Vo^2*K_1/K_2) -> 1947202.1 | L18: =IF(ABS(I18)<ABS(K18),I18,K18) -> 1947202.1 | M18: =IF(H18/1000>$D$23,$D$23,H18/1000) -> 2817.0673 | N18: =L18/1000 -> 1947.2021 | O18: =I18/1000 -> 3295.6919 | P18: =J18*1.43+10 -> 1011.5652 | Q18: =SQRT(M18^2+N18^2) -> 3424.5385 | R18: =M18/SQRT(M18^2+N18^2) -> 0.82261224
H19: =$B$22/20+H18 -> 3018371.4 | I19: =Nm*(SQRT(IF(3/K_3^2*Ii^2*Vo^2-(H19/Nm)^2<0.0000000001,0,3/K_3^2*Ii^2*Vo^2-(H19/Nm)^2))+Vo^2/K_3*K_4) -> 3082341.6 | J19: =SQRT(3)*SQRT((Vo/SQRT(3)*K_1+SQRT(H19^2+I19^2)/SQRT(3)/Vo/Nm*I19/SQRT(H19^2+I19^2)*K_2)^2+(SQRT(H19^2+I19^2)/SQRT(3)/Vo/Nm*H19/SQRT(H19^2+I19^2)*K_2)^2) -> 695.43092 | K19: =Nm*(SQRT(Vi^2*Vo^2/K_2^2-(H19/Nm)^2)-Vo^2*K_1/K_2) -> 1923997 | L19: =IF(ABS(I19)<ABS(K19),I19,K19) -> 1923997 | M19: =IF(H19/1000>$D$23,$D$23,H19/1000) -> 3018.3714 | N19: =L19/1000 -> 1923.997 | O19: =I19/1000 -> 3082.3416 | P19: =J19*1.43+10 -> 1004.4662 | Q19: =SQRT(M19^2+N19^2) -> 3579.4316 | R19: =M19/SQRT(M19^2+N19^2) -> 0.84325439
A20: Vi_max (V) | B20: =($D$8)/Vac_to_Vdc -> 665.38462 | H20: =$B$22/20+H19 -> 3219675.6 | I20: =Nm*(SQRT(IF(3/K_3^2*Ii^2*Vo^2-(H20/Nm)^2<0.0000000001,0,3/K_3^2*Ii^2*Vo^2-(H20/Nm)^2))+Vo^2/K_3*K_4) -> 2833365.4 | J20: =SQRT(3)*SQRT((Vo/SQRT(3)*K_1+SQRT(H20^2+I20^2)/SQRT(3)/Vo/Nm*I20/SQRT(H20^2+I20^2)*K_2)^2+(SQRT(H20^2+I20^2)/SQRT(3)/Vo/Nm*H20/SQRT(H20^2+I20^2)*K_2)^2) -> 689.59245 | K20: =Nm*(SQRT(Vi^2*Vo^2/K_2^2-(H20/Nm)^2)-Vo^2*K_1/K_2) -> 1899167.4 | L20: =IF(ABS(I20)<ABS(K20),I20,K20) -> 1899167.4 | M20: =IF(H20/1000>$D$23,$D$23,H20/1000) -> 3219.6756 | N20: =L20/1000 -> 1899.1674 | O20: =I20/1000 -> 2833.3654 | P20: =J20*1.43+10 -> 996.1172 | Q20: =SQRT(M20^2+N20^2) -> 3738.0674 | R20: =M20/SQRT(M20^2+N20^2) -> 0.8613209
A21: Ii (A) | B21: =IF(B25=1,(IF(B9*B10>B18,B18,B9*B10))*Ii_r,B26) -> 1242.32 | H21: =$B$22/80+H20 -> 3270001.6 | I21: =Nm*(SQRT(IF(3/K_3^2*Ii^2*Vo^2-(H21/Nm)^2<0.0000000001,0,3/K_3^2*Ii^2*Vo^2-(H21/Nm)^2))+Vo^2/K_3*K_4) -> 2764251.7 | J21: =SQRT(3)*SQRT((Vo/SQRT(3)*K_1+SQRT(H21^2+I21^2)/SQRT(3)/Vo/Nm*I21/SQRT(H21^2+I21^2)*K_2)^2+(SQRT(H21^2+I21^2)/SQRT(3)/Vo/Nm*H21/SQRT(H21^2+I21^2)*K_2)^2) -> 687.96295 | K21: =Nm*(SQRT(Vi^2*Vo^2/K_2^2-(H21/Nm)^2)-Vo^2*K_1/K_2) -> 1892705.7 | L21: =IF(ABS(I21)<ABS(K21),I21,K21) -> 1892705.7 | M21: =IF(H21/1000>$D$23,$D$23,H21/1000) -> 3270.0016 | N21: =L21/1000 -> 1892.7057 | O21: =I21/1000 -> 2764.2517 | P21: =J21*1.43+10 -> 993.78702 | Q21: =SQRT(M21^2+N21^2) -> 3778.2595 | R21: =M21/SQRT(M21^2+N21^2) -> 0.86547829
A22: S_max (VA) | B22: =Nm*SQRT(3)*Vo*Ii/K_3^2 -> 4026082.3 | C22: S_base (kVA) | D22: =B22/1000 -> 4026.0823 | H22: =$B$22/80+H21 -> 3320327.6 | I22: =Nm*(SQRT(IF(3/K_3^2*Ii^2*Vo^2-(H22/Nm)^2<0.0000000001,0,3/K_3^2*Ii^2*Vo^2-(H22/Nm)^2))+Vo^2/K_3*K_4) -> 2691900.2 | J22: =SQRT(3)*SQRT((Vo/SQRT(3)*K_1+SQRT(H22^2+I22^2)/SQRT(3)/Vo/Nm*I22/SQRT(H22^2+I22^2)*K_2)^2+(SQRT(H22^2+I22^2)/SQRT(3)/Vo/Nm*H22/SQRT(H22^2+I22^2)*K_2)^2) -> 686.25297 | K22: =Nm*(SQRT(Vi^2*Vo^2/K_2^2-(H22/Nm)^2)-Vo^2*K_1/K_2) -> 1886142 | L22: =IF(ABS(I22)<ABS(K22),I22,K22) -> 1886142 | M22: =IF(H22/1000>$D$23,$D$23,H22/1000) -> 3320.3276 | N22: =L22/1000 -> 1886.142 | O22: =I22/1000 -> 2691.9002 | P22: =J22*1.43+10 -> 991.34175 | Q22: =SQRT(M22^2+N22^2) -> 3818.6525 | R22: =M22/SQRT(M22^2+N22^2) -> 0.86950243
A23: Prated (W) | B23: =Vo*Ii*SQRT(3)*Nm -> 4002276.1 | C23: Prated (kW) | D23: =B23/1000 -> 4002.2761 | H23: =$B$22/80+H22 -> 3370653.6 | I23: =Nm*(SQRT(IF(3/K_3^2*Ii^2*Vo^2-(H23/Nm)^2<0.0000000001,0,3/K_3^2*Ii^2*Vo^2-(H23/Nm)^2))+Vo^2/K_3*K_4) -> 2615988.4 | J23: =SQRT(3)*SQRT((Vo/SQRT(3)*K_1+SQRT(H23^2+I23^2)/SQRT(3)/Vo/Nm*I23/SQRT(H23^2+I23^2)*K_2)^2+(SQRT(H23^2+I23^2)/SQRT(3)/Vo/Nm*H23/SQRT(H23^2+I23^2)*K_2)^2) -> 684.45426 | K23: =Nm*(SQRT(Vi^2*Vo^2/K_2^2-(H23/Nm)^2)-Vo^2*K_1/K_2) -> 1879476.3 | L23: =IF(ABS(I23)<ABS(K23),I23,K23) -> 1879476.3 | M23: =IF(H23/1000>$D$23,$D$23,H23/1000) -> 3370.6536 | N23: =L23/1000 -> 1879.4763 | O23: =I23/1000 -> 2615.9884 | P23: =J23*1.43+10 -> 988.76959 | Q23: =SQRT(M23^2+N23^2) -> 3859.2405 | R23: =M23/SQRT(M23^2+N23^2) -> 0.87339819
H24: =$B$22/80+H23 -> 3420979.7 | I24: =Nm*(SQRT(IF(3/K_3^2*Ii^2*Vo^2-(H24/Nm)^2<0.0000000001,0,3/K_3^2*Ii^2*Vo^2-(H24/Nm)^2))+Vo^2/K_3*K_4) -> 2536130.4 | J24: =SQRT(3)*SQRT((Vo/SQRT(3)*K_1+SQRT(H24^2+I24^2)/SQRT(3)/Vo/Nm*I24/SQRT(H24^2+I24^2)*K_2)^2+(SQRT(H24^2+I24^2)/SQRT(3)/Vo/Nm*H24/SQRT(H24^2+I24^2)*K_2)^2) -> 682.55692 | K24: =Nm*(SQRT(Vi^2*Vo^2/K_2^2-(H24/Nm)^2)-Vo^2*K_1/K_2) -> 1872708.5 | L24: =IF(ABS(I24)<ABS(K24),I24,K24) -> 1872708.5 | M24: =IF(H24/1000>$D$23,$D$23,H24/1000) -> 3420.9797 | N24: =L24/1000 -> 1872.7085 | O24: =I24/1000 -> 2536.1304 | P24: =J24*1.43+10 -> 986.05639 | Q24: =SQRT(M24^2+N24^2) -> 3900.0178 | R24: =M24/SQRT(M24^2+N24^2) -> 0.87717027
A25: GPTech Inverter | B25: 1 | H25: =$B$22/80+H24 -> 3471305.7 | I25: =Nm*(SQRT(IF(3/K_3^2*Ii^2*Vo^2-(H25/Nm)^2<0.0000000001,0,3/K_3^2*Ii^2*Vo^2-(H25/Nm)^2))+Vo^2/K_3*K_4) -> 2451857.1 | J25: =SQRT(3)*SQRT((Vo/SQRT(3)*K_1+SQRT(H25^2+I25^2)/SQRT(3)/Vo/Nm*I25/SQRT(H25^2+I25^2)*K_2)^2+(SQRT(H25^2+I25^2)/SQRT(3)/Vo/Nm*H25/SQRT(H25^2+I25^2)*K_2)^2) -> 680.54894 | K25: =Nm*(SQRT(Vi^2*Vo^2/K_2^2-(H25/Nm)^2)-Vo^2*K_1/K_2) -> 1865838.6 | L25: =IF(ABS(I25)<ABS(K25),I25,K25) -> 1865838.6 | M25: =IF(H25/1000>$D$23,$D$23,H25/1000) -> 3471.3057 | N25: =L25/1000 -> 1865.8386 | O25: =I25/1000 -> 2451.8571 | P25: =J25*1.43+10 -> 983.18499 | Q25: =SQRT(M25^2+N25^2) -> 3940.9792 | R25: =M25/SQRT(M25^2+N25^2) -> 0.88082315
A26: Inverter output current (A) | B26: 1250 | H26: =$B$22/80+H25 -> 3521631.7 | I26: =Nm*(SQRT(IF(3/K_3^2*Ii^2*Vo^2-(H26/Nm)^2<0.0000000001,0,3/K_3^2*Ii^2*Vo^2-(H26/Nm)^2))+Vo^2/K_3*K_4) -> 2362589.4 | J26: =SQRT(3)*SQRT((Vo/SQRT(3)*K_1+SQRT(H26^2+I26^2)/SQRT(3)/Vo/Nm*I26/SQRT(H26^2+I26^2)*K_2)^2+(SQRT(H26^2+I26^2)/SQRT(3)/Vo/Nm*H26/SQRT(H26^2+I26^2)*K_2)^2) -> 678.41548 | K26: =Nm*(SQRT(Vi^2*Vo^2/K_2^2-(H26/Nm)^2)-Vo^2*K_1/K_2) -> 1858866.4 | L26: =IF(ABS(I26)<ABS(K26),I26,K26) -> 1858866.4 | M26: =IF(H26/1000>$D$23,$D$23,H26/1000) -> 3521.6317 | N26: =L26/1000 -> 1858.8664 | O26: =I26/1000 -> 2362.5894 | P26: =J26*1.43+10 -> 980.13414 | Q26: =SQRT(M26^2+N26^2) -> 3982.1193 | R26: =M26/SQRT(M26^2+N26^2) -> 0.88436117
H27: =$B$22/80+H26 -> 3571957.8 | I27: =Nm*(SQRT(IF(3/K_3^2*Ii^2*Vo^2-(H27/Nm)^2<0.0000000001,0,3/K_3^2*Ii^2*Vo^2-(H27/Nm)^2))+Vo^2/K_3*K_4) -> 2267596.9 | J27: =SQRT(3)*SQRT((Vo/SQRT(3)*K_1+SQRT(H27^2+I27^2)/SQRT(3)/Vo/Nm*I27/SQRT(H27^2+I27^2)*K_2)^2+(SQRT(H27^2+I27^2)/SQRT(3)/Vo/Nm*H27/SQRT(H27^2+I27^2)*K_2)^2) -> 676.13781 | K27: =Nm*(SQRT(Vi^2*Vo^2/K_2^2-(H27/Nm)^2)-Vo^2*K_1/K_2) -> 1851792 | L27: =IF(ABS(I27)<ABS(K27),I27,K27) -> 1851792 | M27: =IF(H27/1000>$D$23,$D$23,H27/1000) -> 3571.9578 | N27: =L27/1000 -> 1851.792 | O27: =I27/1000 -> 2267.5969 | P27: =J27*1.43+10 -> 976.87707 | Q27: =SQRT(M27^2+N27^2) -> 4023.4333 | R27: =M27/SQRT(M27^2+N27^2) -> 0.88778848
A28: Set Point Calculation Tool (@Tmax) | C28: Vdc_limited? | D28: 2 | H28: =$B$22/80+H27 -> 3622283.8 | I28: =Nm*(SQRT(IF(3/K_3^2*Ii^2*Vo^2-(H28/Nm)^2<0.0000000001,0,3/K_3^2*Ii^2*Vo^2-(H28/Nm)^2))+Vo^2/K_3*K_4) -> 2165937 | J28: =SQRT(3)*SQRT((Vo/SQRT(3)*K_1+SQRT(H28^2+I28^2)/SQRT(3)/Vo/Nm*I28/SQRT(H28^2+I28^2)*K_2)^2+(SQRT(H28^2+I28^2)/SQRT(3)/Vo/Nm*H28/SQRT(H28^2+I28^2)*K_2)^2) -> 673.69174 | K28: =Nm*(SQRT(Vi^2*Vo^2/K_2^2-(H28/Nm)^2)-Vo^2*K_1/K_2) -> 1844615.1 | L28: =IF(ABS(I28)<ABS(K28),I28,K28) -> 1844615.1 | M28: =IF(H28/1000>$D$23,$D$23,H28/1000) -> 3622.2838 | N28: =L28/1000 -> 1844.6151 | O28: =I28/1000 -> 2165.937 | P28: =J28*1.43+10 -> 973.37918 | Q28: =SQRT(M28^2+N28^2) -> 4064.9163 | R28: =M28/SQRT(M28^2+N28^2) -> 0.89110907
A29: P | B29: 2846 | C29: =IF(B29>D23,D23,B29) -> 2846 | H29: =$B$22/80+H28 -> 3672609.8 | I29: =Nm*(SQRT(IF(3/K_3^2*Ii^2*Vo^2-(H29/Nm)^2<0.0000000001,0,3/K_3^2*Ii^2*Vo^2-(H29/Nm)^2))+Vo^2/K_3*K_4) -> 2056355.2 | J29: =SQRT(3)*SQRT((Vo/SQRT(3)*K_1+SQRT(H29^2+I29^2)/SQRT(3)/Vo/Nm*I29/SQRT(H29^2+I29^2)*K_2)^2+(SQRT(H29^2+I29^2)/SQRT(3)/Vo/Nm*H29/SQRT(H29^2+I29^2)*K_2)^2) -> 671.04507 | K29: =Nm*(SQRT(Vi^2*Vo^2/K_2^2-(H29/Nm)^2)-Vo^2*K_1/K_2) -> 1837335.7 | L29: =IF(ABS(I29)<ABS(K29),I29,K29) -> 1837335.7 | M29: =IF(H29/1000>$D$23,$D$23,H29/1000) -> 3672.6098 | N29: =L29/1000 -> 1837.3357 | O29: =I29/1000 -> 2056.3552 | P29: =J29*1.43+10 -> 969.59445 | Q29: =SQRT(M29^2+N29^2) -> 4106.5637 | R29: =M29/SQRT(M29^2+N29^2) -> 0.89432676
B30: Q_ind_lim | C30: =Nm/1000*(-SQRT(3/K_3^2*Ii^2*Vo^2-($C$29*1000/Nm)^2)+Vo^2*K_4/K_3) -> -2394.8244 | H30: =$B$22/80+H29 -> 3722935.9 | I30: =Nm*(SQRT(IF(3/K_3^2*Ii^2*Vo^2-(H30/Nm)^2<0.0000000001,0,3/K_3^2*Ii^2*Vo^2-(H30/Nm)^2))+Vo^2/K_3*K_4) -> 1937117.4 | J30: =SQRT(3)*SQRT((Vo/SQRT(3)*K_1+SQRT(H30^2+I30^2)/SQRT(3)/Vo/Nm*I30/SQRT(H30^2+I30^2)*K_2)^2+(SQRT(H30^2+I30^2)/SQRT(3)/Vo/Nm*H30/SQRT(H30^2+I30^2)*K_2)^2) -> 668.15328 | K30: =Nm*(SQRT(Vi^2*Vo^2/K_2^2-(H30/Nm)^2)-Vo^2*K_1/K_2) -> 1829953.7 | L30: =IF(ABS(I30)<ABS(K30),I30,K30) -> 1829953.7 | M30: =IF(H30/1000>$D$23,$D$23,H30/1000) -> 3722.9359 | N30: =L30/1000 -> 1829.9537 | O30: =I30/1000 -> 1937.1174 | P30: =J30*1.43+10 -> 965.45919 | Q30: =SQRT(M30^2+N30^2) -> 4148.371 | R30: =M30/SQRT(M30^2+N30^2) -> 0.89744525
B31: Q_cap_lim | C31: =Nm/1000*IF(D28=1,MIN(SQRT(3/K_3^2*Ii^2*Vo^2-($C$29*1000/Nm)^2)+Vo^2*K_4/K_3,SQRT(Vi^2*Vo^2/K_2^2-($C$29*1000/Nm)^2)-Vo^2*K_1/K_2),SQRT(3/K_3^2*Ii^2*Vo^2-($C$29*1000/Nm)^2)+Vo^2*K_4/K_3) -> 3266.8988 | H31: =$B$22/80+H30 -> 3773261.9 | I31: =Nm*(SQRT(IF(3/K_3^2*Ii^2*Vo^2-(H31/Nm)^2<0.0000000001,0,3/K_3^2*Ii^2*Vo^2-(H31/Nm)^2))+Vo^2/K_3*K_4) -> 1805704.3 | J31: =SQRT(3)*SQRT((Vo/SQRT(3)*K_1+SQRT(H31^2+I31^2)/SQRT(3)/Vo/Nm*I31/SQRT(H31^2+I31^2)*K_2)^2+(SQRT(H31^2+I31^2)/SQRT(3)/Vo/Nm*H31/SQRT(H31^2+I31^2)*K_2)^2) -> 664.95164 | K31: =Nm*(SQRT(Vi^2*Vo^2/K_2^2-(H31/Nm)^2)-Vo^2*K_1/K_2) -> 1822469.1 | L31: =IF(ABS(I31)<ABS(K31),I31,K31) -> 1805704.3 | M31: =IF(H31/1000>$D$23,$D$23,H31/1000) -> 3773.2619 | N31: =L31/1000 -> 1805.7043 | O31: =I31/1000 -> 1805.7043 | P31: =J31*1.43+10 -> 960.88084 | Q31: =SQRT(M31^2+N31^2) -> 4183.0698 | R31: =M31/SQRT(M31^2+N31^2) -> 0.90203177
A32: Q | B32: 0 | C32: =IF(B32<C30,C30,IF(B32>C31,C31,B32)) -> 0 | H32: =$B$22/80+H31 -> 3823587.9 | I32: =Nm*(SQRT(IF(3/K_3^2*Ii^2*Vo^2-(H32/Nm)^2<0.0000000001,0,3/K_3^2*Ii^2*Vo^2-(H32/Nm)^2))+Vo^2/K_3*K_4) -> 1658194.6 | J32: =SQRT(3)*SQRT((Vo/SQRT(3)*K_1+SQRT(H32^2+I32^2)/SQRT(3)/Vo/Nm*I32/SQRT(H32^2+I32^2)*K_2)^2+(SQRT(H32^2+I32^2)/SQRT(3)/Vo/Nm*H32/SQRT(H32^2+I32^2)*K_2)^2) -> 661.33937 | K32: =Nm*(SQRT(Vi^2*Vo^2/K_2^2-(H32/Nm)^2)-Vo^2*K_1/K_2) -> 1814881.7 | L32: =IF(ABS(I32)<ABS(K32),I32,K32) -> 1658194.6 | M32: =IF(H32/1000>$D$23,$D$23,H32/1000) -> 3823.5879 | N32: =L32/1000 -> 1658.1946 | O32: =I32/1000 -> 1658.1946 | P32: =J32*1.43+10 -> 955.71529 | Q32: =SQRT(M32^2+N32^2) -> 4167.6653 | R32: =M32/SQRT(M32^2+N32^2) -> 0.91744122
A33: PF | B33: =C29/SQRT(C29^2+C32^2) -> 1 | C33: Io(P,Q) (A) | D33: =SQRT(C29^2+C32^2)/(SQRT(3)*Vo)*1000 -> 2650.224 | H33: =$B$22/80+H32 -> 3873913.9 | I33: =Nm*(SQRT(IF(3/K_3^2*Ii^2*Vo^2-(H33/Nm)^2<0.0000000001,0,3/K_3^2*Ii^2*Vo^2-(H33/Nm)^2))+Vo^2/K_3*K_4) -> 1487837.6 | J33: =SQRT(3)*SQRT((Vo/SQRT(3)*K_1+SQRT(H33^2+I33^2)/SQRT(3)/Vo/Nm*I33/SQRT(H33^2+I33^2)*K_2)^2+(SQRT(H33^2+I33^2)/SQRT(3)/Vo/Nm*H33/SQRT(H33^2+I33^2)*K_2)^2) -> 657.1429 | K33: =Nm*(SQRT(Vi^2*Vo^2/K_2^2-(H33/Nm)^2)-Vo^2*K_1/K_2) -> 1807191.5 | L33: =IF(ABS(I33)<ABS(K33),I33,K33) -> 1487837.6 | M33: =IF(H33/1000>$D$23,$D$23,H33/1000) -> 3873.9139 | N33: =L33/1000 -> 1487.8376 | O33: =I33/1000 -> 1487.8376 | P33: =J33*1.43+10 -> 949.71434 | Q33: =SQRT(M33^2+N33^2) -> 4149.8036 | R33: =M33/SQRT(M33^2+N33^2) -> 0.93351742
A34: Vdc_min(V) | B34: =Vdc_offset+Vac_to_Vdc*SQRT(3)*SQRT(K_1^2*Vo^2/3+K_2^2/3*($C$29^2+$C$32^2)*1000^2/Vo^2/Nm^2+2/3*K_1*K_2*$C$32*1000/Nm) -> 889.39553 | H34: =$B$22/80+H33 -> 3924240 | I34: =Nm*(SQRT(IF(3/K_3^2*Ii^2*Vo^2-(H34/Nm)^2<0.0000000001,0,3/K_3^2*Ii^2*Vo^2-(H34/Nm)^2))+Vo^2/K_3*K_4) -> 1280924.1 | J34: =SQRT(3)*SQRT((Vo/SQRT(3)*K_1+SQRT(H34^2+I34^2)/SQRT(3)/Vo/Nm*I34/SQRT(H34^2+I34^2)*K_2)^2+(SQRT(H34^2+I34^2)/SQRT(3)/Vo/Nm*H34/SQRT(H34^2+I34^2)*K_2)^2) -> 652.0096 | K34: =Nm*(SQRT(Vi^2*Vo^2/K_2^2-(H34/Nm)^2)-Vo^2*K_1/K_2) -> 1799398.2 | L34: =IF(ABS(I34)<ABS(K34),I34,K34) -> 1280924.1 | M34: =IF(H34/1000>$D$23,$D$23,H34/1000) -> 3924.24 | N34: =L34/1000 -> 1280.9241 | O34: =I34/1000 -> 1280.9241 | P34: =J34*1.43+10 -> 942.37372 | Q34: =SQRT(M34^2+N34^2) -> 4128.0051 | R34: =M34/SQRT(M34^2+N34^2) -> 0.95063836
A35: Vac_max(V) | B35: =SQRT(3)*SQRT(K_1^2*Vo^2/3+K_2^2/3*($C$29^2+$C$32^2)*1000^2/Vo^2/Nm^2+2/3*K_1*K_2*$C$32*1000/Nm) -> 614.96191 | H35: =$B$22/80+H34 -> 3974566 | I35: =Nm*(SQRT(IF(3/K_3^2*Ii^2*Vo^2-(H35/Nm)^2<0.0000000001,0,3/K_3^2*Ii^2*Vo^2-(H35/Nm)^2))+Vo^2/K_3*K_4) -> 998459.08 | J35: =SQRT(3)*SQRT((Vo/SQRT(3)*K_1+SQRT(H35^2+I35^2)/SQRT(3)/Vo/Nm*I35/SQRT(H35^2+I35^2)*K_2)^2+(SQRT(H35^2+I35^2)/SQRT(3)/Vo/Nm*H35/SQRT(H35^2+I35^2)*K_2)^2) -> 644.93598 | K35: =Nm*(SQRT(Vi^2*Vo^2/K_2^2-(H35/Nm)^2)-Vo^2*K_1/K_2) -> 1791502 | L35: =IF(ABS(I35)<ABS(K35),I35,K35) -> 998459.08 | M35: =IF(H35/1000>$D$23,$D$23,H35/1000) -> 3974.566 | N35: =L35/1000 -> 998.45908 | O35: =I35/1000 -> 998.45908 | P35: =J35*1.43+10 -> 932.25846 | Q35: =SQRT(M35^2+N35^2) -> 4098.06 | R35: =M35/SQRT(M35^2+N35^2) -> 0.96986526
H36: =$B$22/80+H35 -> 4024892 | I36: =Nm*(SQRT(IF(3/K_3^2*Ii^2*Vo^2-(H36/Nm)^2<0.0000000001,0,3/K_3^2*Ii^2*Vo^2-(H36/Nm)^2))+Vo^2/K_3*K_4) -> 436037.21 | J36: =SQRT(3)*SQRT((Vo/SQRT(3)*K_1+SQRT(H36^2+I36^2)/SQRT(3)/Vo/Nm*I36/SQRT(H36^2+I36^2)*K_2)^2+(SQRT(H36^2+I36^2)/SQRT(3)/Vo/Nm*H36/SQRT(H36^2+I36^2)*K_2)^2) -> 630.66198 | K36: =Nm*(SQRT(Vi^2*Vo^2/K_2^2-(H36/Nm)^2)-Vo^2*K_1/K_2) -> 1783502.6 | L36: =IF(ABS(I36)<ABS(K36),I36,K36) -> 436037.21 | M36: =IF(H36/1000>$D$23,$D$23,H36/1000) -> 4002.2761 | N36: =L36/1000 -> 436.03721 | O36: =I36/1000 -> 436.03721 | P36: =J36*1.43+10 -> 911.84664 | Q36: =SQRT(M36^2+N36^2) -> 4025.9586 | R36: =M36/SQRT(M36^2+N36^2) -> 0.99411756
H37: =-$B$22/80+H36 -> 3974566 | I37: =Nm*(-SQRT(IF(3/K_3^2*Ii^2*Vo^2-(H37/Nm)^2<0.0000000001,0,3/K_3^2*Ii^2*Vo^2-(H37/Nm)^2))+Vo^2/K_3*K_4) -> -126384.66 | J37: =SQRT(3)*SQRT((Vo/SQRT(3)*K_1+SQRT(H37^2+I37^2)/SQRT(3)/Vo/Nm*I37/SQRT(H37^2+I37^2)*K_2)^2+(SQRT(H37^2+I37^2)/SQRT(3)/Vo/Nm*H37/SQRT(H37^2+I37^2)*K_2)^2) -> 615.96184 | K37: =Nm*(-SQRT(Vi^2*Vo^2/K_2^2-(H37/Nm)^2)-Vo^2*K_1/K_2) -> -48542860 | L37: =IF(ABS(I37)<ABS(K37),I37,K37) -> -126384.66 | M37: =IF(H37/1000>$D$23,$D$23,H37/1000) -> 3974.566 | N37: =L37/1000 -> -126.38466 | O37: =I37/1000 -> -126.38466 | P37: =J37*1.43+10 -> 890.82543 | Q37: =SQRT(M37^2+N37^2) -> 3976.5749 | R37: =M37/SQRT(M37^2+N37^2) -> 0.99949482
H38: =-$B$22/80+H37 -> 3924240 | I38: =Nm*(-SQRT(IF(3/K_3^2*Ii^2*Vo^2-(H38/Nm)^2<0.0000000001,0,3/K_3^2*Ii^2*Vo^2-(H38/Nm)^2))+Vo^2/K_3*K_4) -> -408849.7 | J38: =SQRT(3)*SQRT((Vo/SQRT(3)*K_1+SQRT(H38^2+I38^2)/SQRT(3)/Vo/Nm*I38/SQRT(H38^2+I38^2)*K_2)^2+(SQRT(H38^2+I38^2)/SQRT(3)/Vo/Nm*H38/SQRT(H38^2+I38^2)*K_2)^2) -> 608.46931 | K38: =Nm*(-SQRT(Vi^2*Vo^2/K_2^2-(H38/Nm)^2)-Vo^2*K_1/K_2) -> -48550756 | L38: =IF(ABS(I38)<ABS(K38),I38,K38) -> -408849.7 | M38: =IF(H38/1000>$D$23,$D$23,H38/1000) -> 3924.24 | N38: =L38/1000 -> -408.8497 | O38: =I38/1000 -> -408.8497 | P38: =J38*1.43+10 -> 880.11111 | Q38: =SQRT(M38^2+N38^2) -> 3945.4806 | R38: =M38/SQRT(M38^2+N38^2) -> 0.99461646
H39: =-$B$22/80+H38 -> 3873913.9 | I39: =Nm*(-SQRT(IF(3/K_3^2*Ii^2*Vo^2-(H39/Nm)^2<0.0000000001,0,3/K_3^2*Ii^2*Vo^2-(H39/Nm)^2))+Vo^2/K_3*K_4) -> -615763.16 | J39: =SQRT(3)*SQRT((Vo/SQRT(3)*K_1+SQRT(H39^2+I39^2)/SQRT(3)/Vo/Nm*I39/SQRT(H39^2+I39^2)*K_2)^2+(SQRT(H39^2+I39^2)/SQRT(3)/Vo/Nm*H39/SQRT(H39^2+I39^2)*K_2)^2) -> 602.92174 | K39: =Nm*(-SQRT(Vi^2*Vo^2/K_2^2-(H39/Nm)^2)-Vo^2*K_1/K_2) -> -48558549 | L39: =IF(ABS(I39)<ABS(K39),I39,K39) -> -615763.16 | M39: =IF(H39/1000>$D$23,$D$23,H39/1000) -> 3873.9139 | N39: =L39/1000 -> -615.76316 | O39: =I39/1000 -> -615.76316 | P39: =J39*1.43+10 -> 872.17809 | Q39: =SQRT(M39^2+N39^2) -> 3922.5468 | R39: =M39/SQRT(M39^2+N39^2) -> 0.98760171
H40: =-$B$22/80+H39 -> 3823587.9 | I40: =Nm*(-SQRT(IF(3/K_3^2*Ii^2*Vo^2-(H40/Nm)^2<0.0000000001,0,3/K_3^2*Ii^2*Vo^2-(H40/Nm)^2))+Vo^2/K_3*K_4) -> -786120.19 | J40: =SQRT(3)*SQRT((Vo/SQRT(3)*K_1+SQRT(H40^2+I40^2)/SQRT(3)/Vo/Nm*I40/SQRT(H40^2+I40^2)*K_2)^2+(SQRT(H40^2+I40^2)/SQRT(3)/Vo/Nm*H40/SQRT(H40^2+I40^2)*K_2)^2) -> 598.31568 | K40: =Nm*(-SQRT(Vi^2*Vo^2/K_2^2-(H40/Nm)^2)-Vo^2*K_1/K_2) -> -48566240 | L40: =IF(ABS(I40)<ABS(K40),I40,K40) -> -786120.19 | M40: =IF(H40/1000>$D$23,$D$23,H40/1000) -> 3823.5879 | N40: =L40/1000 -> -786.12019 | O40: =I40/1000 -> -786.12019 | P40: =J40*1.43+10 -> 865.59142 | Q40: =SQRT(M40^2+N40^2) -> 3903.5637 | R40: =M40/SQRT(M40^2+N40^2) -> 0.97951211
...

Sheet Curves Value
A1: Warning. These data are manually generated.
A2: Model | B2: =CONCATENATE("PV3WD3HV",Capability!B1) -> PV3WD3HV620 | C2: Vdc_min | D2: 954
C3: Vdc_max | D3: 1130
A5: Curve 1 | C5: Curve 2 | E5: Curve 3 | G5: Curve 4 | I5: Curve 5 | K5: Curve 6 | M5: Curve 7
A6: Vac | B6: T | C6: Vac | D6: T | E6: Vac | F6: T | G6: Vac | H6: T | I6: Vac | J6: T | K6: Vac | L6: T | M6: Vac | N6: T
A7: 620 | B7: 33 | C7: 620 | D7: -5
A8: Vdc | B8: 951.5 | C8: Vdc | D8: 1130 | E8: Vdc | G8: Vdc | I8: Vdc | K8: Vdc | M8: Vdc
A9: P | B9: Q | C9: P | D9: Q | E9: P | F9: Q | G9: P | H9: Q | I9: P | J9: Q | K9: P | L9: Q | M9: P | N9: Q
A10: 0 | B10: 2103.4139 | C10: 0 | D10: 4450.1988
A11: 200.11381 | B11: 2102.628 | C11: 200.11381 | D11: 4445.2077
A12: 401.41792 | B12: 2100.2515 | C12: 401.41792 | D12: 4430.0774
A13: 602.72204 | B13: 2096.284 | C13: 602.72204 | D13: 4404.6918
A14: 804.02616 | B14: 2090.7247 | C14: 804.02616 | D14: 4368.8524
A15: 1005.3303 | B15: 2083.5725 | C15: 1005.3303 | D15: 4322.2699
A16: 1206.6344 | B16: 2074.826 | C16: 1206.6344 | D16: 4264.5522
A17: 1407.9385 | B17: 2064.4838 | C17: 1407.9385 | D17: 4195.1864
A18: 1609.2426 | B18: 2052.5437 | C18: 1609.2426 | D18: 4113.5134
A19: 1810.5467 | B19: 2039.0036 | C19: 1810.5467 | D19: 4018.6918
A20: 2011.8509 | B20: 2023.8609 | C20: 2011.8509 | D20: 3909.6448
A21: 2213.155 | B21: 2007.1128 | C21: 2213.155 | D21: 3784.9831
... A74: -1.1903104 | B74: -3578.1242 | C74: -1.1903104 | D74: -3578.1242

Sheet Ii_Derating
A1: Temperature derating
B2: Ii(T) (A) | E2: Ii(T)(%In)
A3: Temp(ºC) | B3: 35 | C3: 50 | D3: 60 | E3: -20 | F3: =B3 -> 35 | G3: =C3 -> 50 | H3: =D3 -> 60
A4: Ii(A)/Ii(%) | B4: 1172 | C4: =Ii_r -> 1050 | D4: 756 | E4: =F4 -> 1.1161905 | F4: =B4/$C4 -> 1.1161905 | G4: =C4/$C4 -> 1 | H4: =D4/$C4 -> 0.72
A17: Ii DC Voltage derating
A19: DC Voltage(V) | B19: 500 | C19: 950 | D19: 1250 | E19: 1350 | F19: 1500 | G19: 1500
A20: WD3V | B20: 1.15 | C20: 1.15 | D20: 1 | E20: 0.45 | F20: 0.05 | G20: 0
A23: Altitude derating
A25: Altitude | B25: H<1000 | C25: 1000<H<2000 | D25: 2000<H<4000
A26: Operation temperature derating value (ºC/1000m) | B26: 0 | C26: 6 | D26: 7.5
A28: WD3 voltage dependecy on altitude
A30: Altitude(m) | B30: 0 | C30: 2000 | D30: 3000 | E30: 4000
A31: Max DC (Altirude derating) (V) | B31: 1500 | C31: 1500 | D31: =C31*0.88 -> 1320 | E31: =C31*0.78 -> 1170
A32: Max AC(Altitude derating) (V) | B32: 690 | C32: 690 | D32: =C32*0.88 -> 607.2 | E32: =C32*0.78 -> 538.2
B35: Total derating curves example
B36: Warning: The maximum output current of the inverter will also depend on the AC/DC
B37: Pbase | C37: =1050*Capability!$B$1*SQRT(3)*Nm/1000 -> 3382.6952
D39: Vdc
D40: 1250 | E40: 1200 | F40: 1100 | G40: 1000 | H40: 950
B41: %Ii(T) | C41: Temp | D41: =CONCATENATE("S(kVA) @ ",D40,"V") -> S(kVA) @ 1250V | E41: =CONCATENATE("S(kVA) @ ",E40,"V") -> S(kVA) @ 1200V | F41: =CONCATENATE("S(kVA) @ ",F40,"V") -> S(kVA) @ 1100V | G41: =CONCATENATE("S(kVA) @ ",G40,"V") -> S(kVA) @ 1000V | H41: =CONCATENATE("S(kVA) @ ",H40,"V") -> S(kVA) @ 950V
B42: 1.1161905 | C42: -20 | D42: =$B42*$C$37*IF(D$40<=$C$51,$B$51,IF(D$40<=$C$52,$B$52+($B$51-$B$52)/($C$52-$C$51)*($C$52-D$40),IF(D$40<=$C$53,$B$53+($B$52-$B$53)/($C$53-$C$52)*($C$53-D$40),IF(D$40<=$C$54,$B$54+($B$53-$B$54)/($C$54-$C$53)*($C$54-D$40),0)))) -> 3775.7322 | E42: =$B42*$C$37*IF(E$40<=$C$51,$B$51,IF(E$40<=$C$52,$B$52+($B$51-$B$52)/($C$52-$C$51)*($C$52-E$40),IF(E$40<=$C$53,$B$53+($B$52-$B$53)/($C$53-$C$52)*($C$53-E$40),IF(E$40<=$C$54,$B$54+($B$53-$B$54)/($C$54-$C$53)*($C$54-E$40),0)))) -> 3871.3068 | F42: =$B42*$C$37*IF(F$40<=$C$51,$B$51,IF(F$40<=$C$52,$B$52+($B$51-$B$52)/($C$52-$C$51)*($C$52-F$40),IF(F$40<=$C$53,$B$53+($B$52-$B$53)/($C$53-$C$52)*($C$53-F$40),IF(F$40<=$C$54,$B$54+($B$53-$B$54)/($C$54-$C$53)*($C$54-F$40),0)))) -> 4062.4559 | G42: =$B42*$C$37*IF(G$40<=$C$51,$B$51,IF(G$40<=$C$52,$B$52+($B$51-$B$52)/($C$52-$C$51)*($C$52-G$40),IF(G$40<=$C$53,$B$53+($B$52-$B$53)/($C$53-$C$52)*($C$53-G$40),IF(G$40<=$C$54,$B$54+($B$53-$B$54)/($C$54-$C$53)*($C$54-G$40),0)))) -> 4253.605 | H42: =$B42*$C$37*IF(H$40<=$C$51,$B$51,IF(H$40<=$C$52,$B$52+($B$51-$B$52)/($C$52-$C$51)*($C$52-H$40),IF(H$40<=$C$53,$B$53+($B$52-$B$53)/($C$53-$C$52)*($C$53-H$40),IF(H$40<=$C$54,$B$54+($B$53-$B$54)/($C$54-$C$53)*($C$54-H$40),0)))) -> 4349.1796
B43: 1.1161905 | C43: 35 | D43: =$B43*$C$37*IF(D$40<=$C$51,$B$51,IF(D$40<=$C$52,$B$52+($B$51-$B$52)/($C$52-$C$51)*($C$52-D$40),IF(D$40<=$C$53,$B$53+($B$52-$B$53)/($C$53-$C$52)*($C$53-D$40),IF(D$40<=$C$54,$B$54+($B$53-$B$54)/($C$54-$C$53)*($C$54-D$40),0)))) -> 3775.7322 | E43: =$B43*$C$37*IF(E$40<=$C$51,$B$51,IF(E$40<=$C$52,$B$52+($B$51-$B$52)/($C$52-$C$51)*($C$52-E$40),IF(E$40<=$C$53,$B$53+($B$52-$B$53)/($C$53-$C$52)*($C$53-E$40),IF(E$40<=$C$54,$B$54+($B$53-$B$54)/($C$54-$C$53)*($C$54-E$40),0)))) -> 3871.3068 | F43: =$B43*$C$37*IF(F$40<=$C$51,$B$51,IF(F$40<=$C$52,$B$52+($B$51-$B$52)/($C$52-$C$51)*($C$52-F$40),IF(F$40<=$C$53,$B$53+($B$52-$B$53)/($C$53-$C$52)*($C$53-F$40),IF(F$40<=$C$54,$B$54+($B$53-$B$54)/($C$54-$C$53)*($C$54-F$40),0)))) -> 4062.4559 | G43: =$B43*$C$37*IF(G$40<=$C$51,$B$51,IF(G$40<=$C$52,$B$52+($B$51-$B$52)/($C$52-$C$51)*($C$52-G$40),IF(G$40<=$C$53,$B$53+($B$52-$B$53)/($C$53-$C$52)*($C$53-G$40),IF(G$40<=$C$54,$B$54+($B$53-$B$54)/($C$54-$C$53)*($C$54-G$40),0)))) -> 4253.605 | H43: =$B43*$C$37*IF(H$40<=$C$51,$B$51,IF(H$40<=$C$52,$B$52+($B$51-$B$52)/($C$52-$C$51)*($C$52-H$40),IF(H$40<=$C$53,$B$53+($B$52-$B$53)/($C$53-$C$52)*($C$53-H$40),IF(H$40<=$C$54,$B$54+($B$53-$B$54)/($C$54-$C$53)*($C$54-H$40),0)))) -> 4349.1796
B44: 1 | C44: 50 | D44: =$B44*$C$37*IF(D$40<=$C$51,$B$51,IF(D$40<=$C$52,$B$52+($B$51-$B$52)/($C$52-$C$51)*($C$52-D$40),IF(D$40<=$C$53,$B$53+($B$52-$B$53)/($C$53-$C$52)*($C$53-D$40),IF(D$40<=$C$54,$B$54+($B$53-$B$54)/($C$54-$C$53)*($C$54-D$40),0)))) -> 3382.6952 | E44: =$B44*$C$37*IF(E$40<=$C$51,$B$51,IF(E$40<=$C$52,$B$52+($B$51-$B$52)/($C$52-$C$51)*($C$52-E$40),IF(E$40<=$C$53,$B$53+($B$52-$B$53)/($C$53-$C$52)*($C$53-E$40),IF(E$40<=$C$54,$B$54+($B$53-$B$54)/($C$54-$C$53)*($C$54-E$40),0)))) -> 3468.3209 | F44: =$B44*$C$37*IF(F$40<=$C$51,$B$51,IF(F$40<=$C$52,$B$52+($B$51-$B$52)/($C$52-$C$51)*($C$52-F$40),IF(F$40<=$C$53,$B$53+($B$52-$B$53)/($C$53-$C$52)*($C$53-F$40),IF(F$40<=$C$54,$B$54+($B$53-$B$54)/($C$54-$C$53)*($C$54-F$40),0)))) -> 3639.5723 | G44: =$B44*$C$37*IF(G$40<=$C$51,$B$51,IF(G$40<=$C$52,$B$52+($B$51-$B$52)/($C$52-$C$51)*($C$52-G$40),IF(G$40<=$C$53,$B$53+($B$52-$B$53)/($C$53-$C$52)*($C$53-G$40),IF(G$40<=$C$54,$B$54+($B$53-$B$54)/($C$54-$C$53)*($C$54-G$40),0)))) -> 3810.8236 | H44: =$B44*$C$37*IF(H$40<=$C$51,$B$51,IF(H$40<=$C$52,$B$52+($B$51-$B$52)/($C$52-$C$51)*($C$52-H$40),IF(H$40<=$C$53,$B$53+($B$52-$B$53)/($C$53-$C$52)*($C$53-H$40),IF(H$40<=$C$54,$B$54+($B$53-$B$54)/($C$54-$C$53)*($C$54-H$40),0)))) -> 3896.4493
B45: 0.72 | C45: 60 | D45: =$B45*$C$37*IF(D$40<=$C$51,$B$51,IF(D$40<=$C$52,$B$52+($B$51-$B$52)/($C$52-$C$51)*($C$52-D$40),IF(D$40<=$C$53,$B$53+($B$52-$B$53)/($C$53-$C$52)*($C$53-D$40),IF(D$40<=$C$54,$B$54+($B$53-$B$54)/($C$54-$C$53)*($C$54-D$40),0)))) -> 2435.5406 | E45: =$B45*$C$37*IF(E$40<=$C$51,$B$51,IF(E$40<=$C$52,$B$52+($B$51-$B$52)/($C$52-$C$51)*($C$52-E$40),IF(E$40<=$C$53,$B$53+($B$52-$B$53)/($C$53-$C$52)*($C$53-E$40),IF(E$40<=$C$54,$B$54+($B$53-$B$54)/($C$54-$C$53)*($C$54-E$40),0)))) -> 2497.191 | F45: =$B45*$C$37*IF(F$40<=$C$51,$B$51,IF(F$40<=$C$52,$B$52+($B$51-$B$52)/($C$52-$C$51)*($C$52-F$40),IF(F$40<=$C$53,$B$53+($B$52-$B$53)/($C$53-$C$52)*($C$53-F$40),IF(F$40<=$C$54,$B$54+($B$53-$B$54)/($C$54-$C$53)*($C$54-F$40),0)))) -> 2620.492 | G45: =$B45*$C$37*IF(G$40<=$C$51,$B$51,IF(G$40<=$C$52,$B$52+($B$51-$B$52)/($C$52-$C$51)*($C$52-G$40),IF(G$40<=$C$53,$B$53+($B$52-$B$53)/($C$53-$C$52)*($C$53-G$40),IF(G$40<=$C$54,$B$54+($B$53-$B$54)/($C$54-$C$53)*($C$54-G$40),0)))) -> 2743.793 | H45: =$B45*$C$37*IF(H$40<=$C$51,$B$51,IF(H$40<=$C$52,$B$52+($B$51-$B$52)/($C$52-$C$51)*($C$52-H$40),IF(H$40<=$C$53,$B$53+($B$52-$B$53)/($C$53-$C$52)*($C$53-H$40),IF(H$40<=$C$54,$B$54+($B$53-$B$54)/($C$54-$C$53)*($C$54-H$40),0)))) -> 2805.4435
D47: Temp (H modified)
D48: 30 | E48: 40 | F48: 50
B49: %Ii(V) | C49: Vdc | D49: =CONCATENATE("S(kVA) @ ",D48,"ºC") -> S(kVA) @ 30ºC | E49: =CONCATENATE("S(kVA) @ ",E48,"ºC") -> S(kVA) @ 40ºC | F49: =CONCATENATE("S(kVA) @ ",F48,"ºC") -> S(kVA) @ 50ºC
B50: 1.1518771 | C50: 500 | D50: =$B50*$C$37*IF(D$48<=$C$43,$B$43,IF(D$48<=$C$44,$B$44+($B$43-$B$44)/($C$44-$C$43)*($C$44-D$48),IF(D$48<=$C$45,$B$45+($B$44-$B$45)/($C$45-$C$44)*($C$45-D$48),0))) -> 4349.1796 | E50: =$B50*$C$37*IF(E$48<=$C$43,$B$43,IF(E$48<=$C$44,$B$44+($B$43-$B$44)/($C$44-$C$43)*($C$44-E$48),IF(E$48<=$C$45,$B$45+($B$44-$B$45)/($C$45-$C$44)*($C$45-E$48),0))) -> 4198.2695 | F50: =$B50*$C$37*IF(F$48<=$C$43,$B$43,IF(F$48<=$C$44,$B$44+($B$43-$B$44)/($C$44-$C$43)*($C$44-F$48),IF(F$48<=$C$45,$B$45+($B$44-$B$45)/($C$45-$C$44)*($C$45-F$48),0))) -> 3896.4493
B51: 1.1518771 | C51: 950 | D51: =$B51*$C$37*IF(D$48<=$C$43,$B$43,IF(D$48<=$C$44,$B$44+($B$43-$B$44)/($C$44-$C$43)*($C$44-D$48),IF(D$48<=$C$45,$B$45+($B$44-$B$45)/($C$45-$C$44)*($C$45-D$48),0))) -> 4349.1796 | E51: =$B51*$C$37*IF(E$48<=$C$43,$B$43,IF(E$48<=$C$44,$B$44+($B$43-$B$44)/($C$44-$C$43)*($C$44-E$48),IF(E$48<=$C$45,$B$45+($B$44-$B$45)/($C$45-$C$44)*($C$45-E$48),0))) -> 4198.2695 | F51: =$B51*$C$37*IF(F$48<=$C$43,$B$43,IF(F$48<=$C$44,$B$44+($B$43-$B$44)/($C$44-$C$43)*($C$44-F$48),IF(F$48<=$C$45,$B$45+($B$44-$B$45)/($C$45-$C$44)*($C$45-F$48),0))) -> 3896.4493
B52: 1 | C52: 1250 | D52: =$B52*$C$37*IF(D$48<=$C$43,$B$43,IF(D$48<=$C$44,$B$44+($B$43-$B$44)/($C$44-$C$43)*($C$44-D$48),IF(D$48<=$C$45,$B$45+($B$44-$B$45)/($C$45-$C$44)*($C$45-D$48),0))) -> 3775.7322 | E52: =$B52*$C$37*IF(E$48<=$C$43,$B$43,IF(E$48<=$C$44,$B$44+($B$43-$B$44)/($C$44-$C$43)*($C$44-E$48),IF(E$48<=$C$45,$B$45+($B$44-$B$45)/($C$45-$C$44)*($C$45-E$48),0))) -> 3644.7199 | F52: =$B52*$C$37*IF(F$48<=$C$43,$B$43,IF(F$48<=$C$44,$B$44+($B$43-$B$44)/($C$44-$C$43)*($C$44-F$48),IF(F$48<=$C$45,$B$45+($B$44-$B$45)/($C$45-$C$44)*($C$45-F$48),0))) -> 3382.6952
B53: 0.45 | C53: 1350 | D53: =$B53*$C$37*IF(D$48<=$C$43,$B$43,IF(D$48<=$C$44,$B$44+($B$43-$B$44)/($C$44-$C$43)*($C$44-D$48),IF(D$48<=$C$45,$B$45+($B$44-$B$45)/($C$45-$C$44)*($C$45-D$48),0))) -> 1699.0795 | E53: =$B53*$C$37*IF(E$48<=$C$43,$B$43,IF(E$48<=$C$44,$B$44+($B$43-$B$44)/($C$44-$C$43)*($C$44-E$48),IF(E$48<=$C$45,$B$45+($B$44-$B$45)/($C$45-$C$44)*($C$45-E$48),0))) -> 1640.1239 | F53: =$B53*$C$37*IF(F$48<=$C$43,$B$43,IF(F$48<=$C$44,$B$44+($B$43-$B$44)/($C$44-$C$43)*($C$44-F$48),IF(F$48<=$C$45,$B$45+($B$44-$B$45)/($C$45-$C$44)*($C$45-F$48),0))) -> 1522.2129
B54: 0.05 | C54: 1500 | D54: =$B54*$C$37*IF(D$48<=$C$43,$B$43,IF(D$48<=$C$44,$B$44+($B$43-$B$44)/($C$44-$C$43)*($C$44-D$48),IF(D$48<=$C$45,$B$45+($B$44-$B$45)/($C$45-$C$44)*($C$45-D$48),0))) -> 188.78661 | E54: =$B54*$C$37*IF(E$48<=$C$43,$B$43,IF(E$48<=$C$44,$B$44+($B$43-$B$44)/($C$44-$C$43)*($C$44-E$48),IF(E$48<=$C$45,$B$45+($B$44-$B$45)/($C$45-$C$44)*($C$45-E$48),0))) -> 182.23599 | F54: =$B54*$C$37*IF(F$48<=$C$43,$B$43,IF(F$48<=$C$44,$B$44+($B$43-$B$44)/($C$44-$C$43)*($C$44-F$48),IF(F$48<=$C$45,$B$45+($B$44-$B$45)/($C$45-$C$44)*($C$45-F$48),0))) -> 169.13476

Sheet aux
A1: Ii_rated | B1: 1050 | M1: Inverter voltages | AC1: Si
B2: =1/0.8645 -> 1.156738 | M2: 400 | AC2: No
M3: 440
M4: 480
M5: 530
B6: deltaT | C6: =IF(Capability!B6>2000,(Capability!B6-2000)*H8/1000+G8,IF(Capability!B6>1000,(Capability!B6-1000)*G8/1000,0)) -> 11.25 | M6: 560
B7: Temperature | C7: Rating | D7: STEP1 | E7: STEP2 | G7: Delta T/1000m (ºC/1000m).1000< H <2000 | H7: Delta T/1000m (ºC/1000m). H>2000m | M7: 575
B8: -20 | C8: =C11 -> 1.1161905 | D8: =IF(C8*$E$33>$H$33,$H$33,C8*$E$33) -> 1.1831619 | E8: =IF(C8*$E$34>$H$33,$H$33,C8*$E$34) -> 1.1831619 | G8: 6 | H8: 7.5 | M8: 590
B9: -10 | C9: =C11 -> 1.1161905 | D9: =IF(C9*$E$33>$H$33,$H$33,C9*$E$33) -> 1.1831619 | E9: =IF(C9*$E$34>$H$33,$H$33,C9*$E$34) -> 1.1831619 | M9: 605
B10: 0 | C10: =C11 -> 1.1161905 | D10: =IF(C10*$E$33>$H$33,$H$33,C10*$E$33) -> 1.1831619 | E10: =IF(C10*$E$34>$H$33,$H$33,C10*$E$34) -> 1.1831619 | M10: 620
B11: 35 | C11: =1172/1050 -> 1.1161905 | D11: =IF(C11*$E$33>$H$33,$H$33,C11*$E$33) -> 1.1831619 | E11: =IF(C11*$E$34>$H$33,$H$33,C11*$E$34) -> 1.1831619 | M11: 630
B12: 50 | C12: =1050/1050 -> 1 | D12: =IF(C12*$E$33>$H$33,$H$33,C12*$E$33) -> 1.15 | E12: =IF(C12*$E$34>$H$33,$H$33,C12*$E$34) -> 1.15 | M12: 650
B13: 60 | C13: =756/1050 -> 0.72 | D13: =IF(C13*$E$33>$H$33,$H$33,C13*$E$33) -> 0.828 | E13: =IF(C13*$E$34>$H$33,$H$33,C13*$E$34) -> 0.828 | M13: 660
M14: 690
B16: Vdc | C16: Rating
B17: 950 | C17: 1.15 | D17: Desactiva Vdc uprating poniendo este valor a 100%. Activarlo poniendolo a 115,2%
B18: 1250 | C18: =1172/1172 -> 1
B19: 1350 | C19: 0.45
B20: 1500 | C20: 0.05
A22: Li (H) | B22: =130*10^-6 -> 0.00013
A23: Co (F) | B23: =1200*10^-6 -> 0.0012
A24: Lo (H) | B24: =25*10^-6 -> 2.5e-05
A26: k1 (wg) | B26: =1-Li*Co*wg*wg -> 0.98460342
A27: k2 (wg) | B27: =Lo*wg+Li*wg*(1-Co*Lo*wg^2) -> 0.048573762
A28: k3 (wg) | B28: =1-Lo*Co*wg^2 -> 0.99703912
A29: k4 (wg) | B29: =Co*wg -> 0.37699112
B32: Ii | C32: Io | D32: Vdc | E32: Vdc_min derating | G32: Ii_lim
